Workbook

Sheet X TKJ 1
A16: DAFTAR HADIR PESERTA DIDIK SEMESTER GENAP
A17: SMK TARUNA BHAKTI
A18: TAHUN AJARAN 2025/2026
A20: SEMESTER GENAP | Y20: KELAS/TINGKAT : X TKJ 1
A21: NO | B21: NIPD | C21: NAMA PESERTA DIDIK | D21: JK | E21: JANUARI | H21: FEBRUARI | K21: MARET | N21: APRIL | Q21: MEI | T21: DESEMBER | W21: TOTAL ABSENSI
E22: S | F22: I | G22: A | H22: S | I22: I | J22: A | K22: S | L22: I | M22: A | N22: S | O22: I | P22: A | Q22: S | R22: I | S22: A | T22: S | U22: I | V22: A | W22: S | X22: I | Y22: A | Z22: T
A23: 1 | B23: 252610231 | C23: Abimanyu Pratama | D23: L | E23: 0 | F23: 0 | G23: 0 | H23: 0 | I23: 0 | J23: 0 | K23: 0 | L23: 0 | M23: 0 | N23: 0 | O23: 0 | P23: 0 | W23: =SUM(E23,H23,K23,N23,Q23,T23) -> 0 | X23: =SUM(F23,I23,L23,O23,R23,U23) -> 0 | Y23: =SUM(G23,J23,M23,P23,S23,V23) -> 0 | Z23: =SUM(W23:Y23) -> 0
A24: 2 | B24: 252610232 | C24: Adelia Setyawan | D24: P | E24: 0 | F24: 0 | G24: 0 | H24: 0 | I24: 0 | J24: 0 | K24: 0 | L24: 1 | M24: 0 | N24: 0 | O24: 0 | P24: 0 | W24: =SUM(E24,H24,K24,N24,Q24,T24) -> 0 | X24: =SUM(F24,I24,L24,O24,R24,U24) -> 1 | Y24: =SUM(G24,J24,M24,P24,S24,V24) -> 0 | Z24: =SUM(W24:Y24) -> 1
A25: 3 | B25: 252610233 | C25: Akbar Kurniawan Putra | D25: L | E25: 0 | F25: 0 | G25: 0 | H25: 0 | I25: 0 | J25: 0 | K25: 0 | L25: 0 | M25: 0 | N25: 0 | O25: 0 | P25: 0 | W25: =SUM(E25,H25,K25,N25,Q25,T25) -> 0 | X25: =SUM(F25,I25,L25,O25,R25,U25) -> 0 | Y25: =SUM(G25,J25,M25,P25,S25,V25) -> 0 | Z25: =SUM(W25:Y25) -> 0
A26: 4 | B26: 252610234 | C26: Alfiah Damayanti | D26: P | E26: 0 | F26: 0 | G26: 0 | H26: 0 | I26: 0 | J26: 0 | K26: 0 | L26: 0 | M26: 0 | N26: 1 | O26: 0 | P26: 0 | W26: =SUM(E26,H26,K26,N26,Q26,T26) -> 1 | X26: =SUM(F26,I26,L26,O26,R26,U26) -> 0 | Y26: =SUM(G26,J26,M26,P26,S26,V26) -> 0 | Z26: =SUM(W26:Y26) -> 1
A27: 5 | B27: 252610235 | C27: Andhika Saputra | D27: L | E27: 0 | F27: 0 | G27: 0 | H27: 0 | I27: 0 | J27: 0 | K27: 1 | L27: 0 | M27: 0 | N27: 0 | O27: 0 | P27: 0 | W27: =SUM(E27,H27,K27,N27,Q27,T27) -> 1 | X27: =SUM(F27,I27,L27,O27,R27,U27) -> 0 | Y27: =SUM(G27,J27,M27,P27,S27,V27) -> 0 | Z27: =SUM(W27:Y27) -> 1
A28: 6 | B28: 252610236 | C28: Aulia Fatoni | D28: L | E28: 1 | F28: 0 | G28: 0 | H28: 0 | I28: 0 | J28: 0 | K28: 0 | L28: 0 | M28: 0 | N28: 0 | O28: 0 | P28: 0 | W28: =SUM(E28,H28,K28,N28,Q28,T28) -> 1 | X28: =SUM(F28,I28,L28,O28,R28,U28) -> 0 | Y28: =SUM(G28,J28,M28,P28,S28,V28) -> 0 | Z28: =SUM(W28:Y28) -> 1
A29: 7 | B29: 252610237 | C29: Dafa Rizky Prayitno | D29: L | E29: 1 | F29: 0 | G29: 0 | H29: 0 | I29: 0 | J29: 0 | K29: 1 | L29: 0 | M29: 0 | N29: 0 | O29: 0 | P29: 1 | W29: =SUM(E29,H29,K29,N29,Q29,T29) -> 2 | X29: =SUM(F29,I29,L29,O29,R29,U29) -> 0 | Y29: =SUM(G29,J29,M29,P29,S29,V29) -> 1 | Z29: =SUM(W29:Y29) -> 3
A30: 8 | B30: 252610238 | C30: Efridonta Mburakta Ginting | D30: L | E30: 0 | F30: 1 | G30: 0 | H30: 0 | I30: 0 | J30: 0 | K30: 0 | L30: 0 | M30: 0 | N30: 0 | O30: 0 | P30: 1 | W30: =SUM(E30,H30,K30,N30,Q30,T30) -> 0 | X30: =SUM(F30,I30,L30,O30,R30,U30) -> 1 | Y30: =SUM(G30,J30,M30,P30,S30,V30) -> 1 | Z30: =SUM(W30:Y30) -> 2
A31: 9 | B31: 252610239 | C31: Fabyan Danis Izwan | D31: L | E31: 0 | F31: 0 | G31: 0 | H31: 0 | I31: 0 | J31: 0 | K31: 0 | L31: 0 | M31: 0 | N31: 0 | O31: 0 | P31: 1 | W31: =SUM(E31,H31,K31,N31,Q31,T31) -> 0 | X31: =SUM(F31,I31,L31,O31,R31,U31) -> 0 | Y31: =SUM(G31,J31,M31,P31,S31,V31) -> 1 | Z31: =SUM(W31:Y31) -> 1
A32: 10 | B32: 252610240 | C32: Fachri Achmad | D32: L | E32: 1 | F32: 0 | G32: 0 | H32: 0 | I32: 0 | J32: 0 | K32: 1 | L32: 0 | M32: 0 | N32: 0 | O32: 0 | P32: 0 | W32: =SUM(E32,H32,K32,N32,Q32,T32) -> 2 | X32: =SUM(F32,I32,L32,O32,R32,U32) -> 0 | Y32: =SUM(G32,J32,M32,P32,S32,V32) -> 0 | Z32: =SUM(W32:Y32) -> 2
A33: 11 | B33: 252610241 | C33: Fahri Qinanda Alfiansyah | D33: L | E33: 1 | F33: 0 | G33: 0 | H33: 1 | I33: 0 | J33: 0 | K33: 0 | L33: 0 | M33: 0 | N33: 0 | O33: 0 | P33: 0 | W33: =SUM(E33,H33,K33,N33,Q33,T33) -> 2 | X33: =SUM(F33,I33,L33,O33,R33,U33) -> 0 | Y33: =SUM(G33,J33,M33,P33,S33,V33) -> 0 | Z33: =SUM(W33:Y33) -> 2
A34: 12 | B34: 252610242 | C34: Faiz Mufid Dilawar | D34: L | E34: 0 | F34: 1 | G34: 0 | H34: 0 | I34: 0 | J34: 0 | K34: 0 | L34: 0 | M34: 0 | N34: 0 | O34: 0 | P34: 0 | W34: =SUM(E34,H34,K34,N34,Q34,T34) -> 0 | X34: =SUM(F34,I34,L34,O34,R34,U34) -> 1 | Y34: =SUM(G34,J34,M34,P34,S34,V34) -> 0 | Z34: =SUM(W34:Y34) -> 1
A35: 13 | B35: 252610243 | C35: Farel Rizky Febrianto | D35: L | E35: 2 | F35: 0 | G35: 0 | H35: 0 | I35: 0 | J35: 0 | K35: 0 | L35: 0 | M35: 0 | N35: 0 | O35: 0 | P35: 0 | W35: =SUM(E35,H35,K35,N35,Q35,T35) -> 2 | X35: =SUM(F35,I35,L35,O35,R35,U35) -> 0 | Y35: =SUM(G35,J35,M35,P35,S35,V35) -> 0 | Z35: =SUM(W35:Y35) -> 2
A36: 14 | B36: 252610244 | C36: Farhan Fadhlurrohman Salim | D36: L | E36: 0 | F36: 0 | G36: 0 | H36: 0 | I36: 0 | J36: 0 | K36: 0 | L36: 0 | M36: 0 | N36: 0 | O36: 0 | P36: 0 | W36: =SUM(E36,H36,K36,N36,Q36,T36) -> 0 | X36: =SUM(F36,I36,L36,O36,R36,U36) -> 0 | Y36: =SUM(G36,J36,M36,P36,S36,V36) -> 0 | Z36: =SUM(W36:Y36) -> 0
A37: 15 | B37: 252610245 | C37: Farras Sakhi Altafa | D37: L | E37: 2 | F37: 1 | G37: 0 | H37: 0 | I37: 0 | J37: 0 | K37: 1 | L37: 0 | M37: 0 | N37: 1 | O37: 0 | P37: 0 | W37: =SUM(E37,H37,K37,N37,Q37,T37) -> 4 | X37: =SUM(F37,I37,L37,O37,R37,U37) -> 1 | Y37: =SUM(G37,J37,M37,P37,S37,V37) -> 0 | Z37: =SUM(W37:Y37) -> 5
A38: 16 | B38: 252610246 | C38: Fausta Akbar Syandana | D38: L | E38: 2 | F38: 0 | G38: 0 | H38: 0 | I38: 0 | J38: 0 | K38: 0 | L38: 0 | M38: 0 | N38: 0 | O38: 0 | P38: 0 | W38: =SUM(E38,H38,K38,N38,Q38,T38) -> 2 | X38: =SUM(F38,I38,L38,O38,R38,U38) -> 0 | Y38: =SUM(G38,J38,M38,P38,S38,V38) -> 0 | Z38: =SUM(W38:Y38) -> 2
A39: 17 | B39: 252610247 | C39: Galuh Garnadi | D39: L | E39: 0 | F39: 0 | G39: 0 | H39: 2 | I39: 0 | J39: 0 | K39: 0 | L39: 0 | M39: 0 | N39: 0 | O39: 0 | P39: 0 | W39: =SUM(E39,H39,K39,N39,Q39,T39) -> 2 | X39: =SUM(F39,I39,L39,O39,R39,U39) -> 0 | Y39: =SUM(G39,J39,M39,P39,S39,V39) -> 0 | Z39: =SUM(W39:Y39) -> 2
A40: 18 | B40: 252610248 | C40: Hadziq Daffa Syahroni | D40: L | E40: 0 | F40: 0 | G40: 0 | H40: 0 | I40: 0 | J40: 0 | K40: 0 | L40: 0 | M40: 0 | N40: 0 | O40: 0 | P40: 0 | W40: =SUM(E40,H40,K40,N40,Q40,T40) -> 0 | X40: =SUM(F40,I40,L40,O40,R40,U40) -> 0 | Y40: =SUM(G40,J40,M40,P40,S40,V40) -> 0 | Z40: =SUM(W40:Y40) -> 0
A41: 19 | B41: 252610249 | C41: Ilham Suryo Wicaksono | D41: L | E41: 1 | F41: 0 | G41: 1 | H41: 0 | I41: 0 | J41: 0 | K41: 0 | L41: 0 | M41: 0 | N41: 1 | O41: 0 | P41: 1 | W41: =SUM(E41,H41,K41,N41,Q41,T41) -> 2 | X41: =SUM(F41,I41,L41,O41,R41,U41) -> 0 | Y41: =SUM(G41,J41,M41,P41,S41,V41) -> 2 | Z41: =SUM(W41:Y41) -> 4
A42: 20 | B42: 252610250 | C42: Kurniawan Dwizon | D42: L | E42: 3 | F42: 0 | G42: 1 | H42: 0 | I42: 0 | J42: 0 | K42: 5 | L42: 0 | M42: 0 | N42: 3 | O42: 0 | P42: 0 | W42: =SUM(E42,H42,K42,N42,Q42,T42) -> 11 | X42: =SUM(F42,I42,L42,O42,R42,U42) -> 0 | Y42: =SUM(G42,J42,M42,P42,S42,V42) -> 1 | Z42: =SUM(W42:Y42) -> 12
A43: 21 | B43: 252610251 | C43: Kurniawan Halomoan | D43: L | E43: 1 | F43: 1 | G43: 2 | H43: 0 | I43: 0 | J43: 0 | K43: 1 | L43: 0 | M43: 0 | N43: 1 | O43: 1 | P43: 0 | W43: =SUM(E43,H43,K43,N43,Q43,T43) -> 3 | X43: =SUM(F43,I43,L43,O43,R43,U43) -> 2 | Y43: =SUM(G43,J43,M43,P43,S43,V43) -> 2 | Z43: =SUM(W43:Y43) -> 7
A44: 22 | B44: 252610252 | C44: M. Rafiq Arrasyid | D44: L | E44: 1 | F44: 1 | G44: 0 | H44: 0 | I44: 0 | J44: 0 | K44: 0 | L44: 0 | M44: 1 | N44: 0 | O44: 0 | P44: 0 | W44: =SUM(E44,H44,K44,N44,Q44,T44) -> 1 | X44: =SUM(F44,I44,L44,O44,R44,U44) -> 1 | Y44: =SUM(G44,J44,M44,P44,S44,V44) -> 1 | Z44: =SUM(W44:Y44) -> 3
A45: 23 | B45: 252610253 | C45: M. Rais Athalah Ramadan | D45: L | E45: 0 | F45: 0 | G45: 0 | H45: 0 | I45: 0 | J45: 0 | K45: 0 | L45: 0 | M45: 0 | N45: 0 | O45: 0 | P45: 0 | W45: =SUM(E45,H45,K45,N45,Q45,T45) -> 0 | X45: =SUM(F45,I45,L45,O45,R45,U45) -> 0 | Y45: =SUM(G45,J45,M45,P45,S45,V45) -> 0 | Z45: =SUM(W45:Y45) -> 0
A46: 24 | B46: 252610255 | C46: Muhamad Ifgan Arly Habsi | D46: L | E46: 1 | F46: 0 | G46: 0 | H46: 0 | I46: 0 | J46: 0 | K46: 0 | L46: 0 | M46: 0 | N46: 0 | O46: 0 | P46: 0 | W46: =SUM(E46,H46,K46,N46,Q46,T46) -> 1 | X46: =SUM(F46,I46,L46,O46,R46,U46) -> 0 | Y46: =SUM(G46,J46,M46,P46,S46,V46) -> 0 | Z46: =SUM(W46:Y46) -> 1
A47: 25 | B47: 252610256 | C47: Muhamad Reza Fahlevi | D47: L | E47: 1 | F47: 0 | G47: 0 | H47: 0 | I47: 0 | J47: 0 | K47: 0 | L47: 0 | M47: 0 | N47: 0 | O47: 0 | P47: 0 | W47: =SUM(E47,H47,K47,N47,Q47,T47) -> 1 | X47: =SUM(F47,I47,L47,O47,R47,U47) -> 0 | Y47: =SUM(G47,J47,M47,P47,S47,V47) -> 0 | Z47: =SUM(W47:Y47) -> 1
A48: 26 | B48: 252610257 | C48: Raihan Meydifat Saputra Ismail | D48: L | E48: 1 | F48: 1 | G48: 1 | H48: 0 | I48: 0 | J48: 0 | K48: 0 | L48: 0 | M48: 0 | N48: 0 | O48: 0 | P48: 1 | W48: =SUM(E48,H48,K48,N48,Q48,T48) -> 1 | X48: =SUM(F48,I48,L48,O48,R48,U48) -> 1 | Y48: =SUM(G48,J48,M48,P48,S48,V48) -> 2 | Z48: =SUM(W48:Y48) -> 4
A49: 27 | B49: 252610258 | C49: Renchus Krismes Silalahi | D49: L | E49: 1 | F49: 0 | G49: 0 | H49: 1 | I49: 0 | J49: 0 | K49: 1 | L49: 1 | M49: 3 | N49: 0 | O49: 0 | P49: 1 | W49: =SUM(E49,H49,K49,N49,Q49,T49) -> 3 | X49: =SUM(F49,I49,L49,O49,R49,U49) -> 1 | Y49: =SUM(G49,J49,M49,P49,S49,V49) -> 4 | Z49: =SUM(W49:Y49) -> 8
A50: 28 | B50: 252610259 | C50: Rizki Arhab Arbain | D50: L | E50: 0 | F50: 0 | G50: 0 | H50: 0 | I50: 0 | J50: 0 | K50: 1 | L50: 1 | M50: 0 | N50: 0 | O50: 0 | P50: 0 | W50: =SUM(E50,H50,K50,N50,Q50,T50) -> 1 | X50: =SUM(F50,I50,L50,O50,R50,U50) -> 1 | Y50: =SUM(G50,J50,M50,P50,S50,V50) -> 0 | Z50: =SUM(W50:Y50) -> 2
A51: 29 | B51: 252610260 | C51: Rizky Raditya | D51: L | E51: 2 | F51: 0 | G51: 0 | H51: 0 | I51: 0 | J51: 0 | K51: 2 | L51: 0 | M51: 0 | N51: 2 | O51: 0 | P51: 0 | W51: =SUM(E51,H51,K51,N51,Q51,T51) -> 6 | X51: =SUM(F51,I51,L51,O51,R51,U51) -> 0 | Y51: =SUM(G51,J51,M51,P51,S51,V51) -> 0 | Z51: =SUM(W51:Y51) -> 6
A52: 30 | B52: 252610261 | C52: Sandy Ahmad Khoiriza | D52: L | E52: 1 | F52: 1 | G52: 0 | H52: 0 | I52: 0 | J52: 0 | K52: 1 | L52: 0 | M52: 1 | N52: 0 | O52: 0 | P52: 0 | W52: =SUM(E52,H52,K52,N52,Q52,T52) -> 2 | X52: =SUM(F52,I52,L52,O52,R52,U52) -> 1 | Y52: =SUM(G52,J52,M52,P52,S52,V52) -> 1 | Z52: =SUM(W52:Y52) -> 4
A53: 31 | B53: 252610262 | C53: Shaleh Al Fauzan Hilal Ahmar | D53: L | E53: 2 | F53: 0 | G53: 0 | H53: 0 | I53: 0 | J53: 0 | K53: 1 | L53: 1 | M53: 0 | N53: 0 | O53: 0 | P53: 1 | W53: =SUM(E53,H53,K53,N53,Q53,T53) -> 3 | X53: =SUM(F53,I53,L53,O53,R53,U53) -> 1 | Y53: =SUM(G53,J53,M53,P53,S53,V53) -> 1 | Z53: =SUM(W53:Y53) -> 5
A54: 32 | B54: 252610263 | C54: Shara Nuraini Fajrin | D54: P | E54: 0 | F54: 1 | G54: 0 | H54: 0 | I54: 0 | J54: 0 | K54: 0 | L54: 0 | M54: 0 | N54: 0 | O54: 0 | P54: 0 | W54: =SUM(E54,H54,K54,N54,Q54,T54) -> 0 | X54: =SUM(F54,I54,L54,O54,R54,U54) -> 1 | Y54: =SUM(G54,J54,M54,P54,S54,V54) -> 0 | Z54: =SUM(W54:Y54) -> 1
A55: 33 | B55: 252610264 | C55: Syach Qibran Fahrezi A | D55: L | E55: 1 | F55: 0 | G55: 0 | H55: 0 | I55: 0 | J55: 0 | K55: 0 | L55: 0 | M55: 0 | N55: 1 | O55: 0 | P55: 0 | W55: =SUM(E55,H55,K55,N55,Q55,T55) -> 2 | X55: =SUM(F55,I55,L55,O55,R55,U55) -> 0 | Y55: =SUM(G55,J55,M55,P55,S55,V55) -> 0 | Z55: =SUM(W55:Y55) -> 2
A56: 34 | B56: 252610265 | C56: Syakila Berlianda Putri Zulisa | D56: P | E56: 0 | F56: 1 | G56: 0 | H56: 0 | I56: 0 | J56: 0 | K56: 0 | L56: 0 | M56: 0 | N56: 3 | O56: 0 | P56: 0 | W56: =SUM(E56,H56,K56,N56,Q56,T56) -> 3 | X56: =SUM(F56,I56,L56,O56,R56,U56) -> 1 | Y56: =SUM(G56,J56,M56,P56,S56,V56) -> 0 | Z56: =SUM(W56:Y56) -> 4
...

Sheet X TKJ 2
A16: DAFTAR HADIR PESERTA DIDIK SEMESTER GENAP
A17: SMK TARUNA BHAKTI
A18: TAHUN AJARAN 2025/2026
A20: ='X TKJ 1'!A20 -> SEMESTER GENAP | Y20: KELAS/TINGKAT : X TKJ 2
A21: NO | B21: NIPD | C21: NAMA PESERTA DIDIK | D21: JK | E21: JANUARI | H21: FEBRUARI | K21: MARET | N21: APRIL | Q21: MEI | T21: DESEMBER | W21: TOTAL ABSENSI
E22: S | F22: I | G22: A | H22: S | I22: I | J22: A | K22: S | L22: I | M22: A | N22: S | O22: I | P22: A | Q22: S | R22: I | S22: A | T22: S | U22: I | V22: A | W22: S | X22: I | Y22: A | Z22: T
A23: 1 | B23: 252610269 | C23: Achmad Ariyadana | D23: L | E23: 0 | F23: 0 | G23: 0 | H23: 0 | I23: 0 | J23: 0 | K23: 0 | L23: 0 | M23: 0 | N23: 1 | O23: 0 | P23: 0 | W23: =SUM(E23,H23,K23,N23,Q23,T23) -> 1 | X23: =SUM(F23,I23,L23,O23,R23,U23) -> 0 | Y23: =SUM(G23,J23,M23,P23,S23,V23) -> 0 | Z23: =SUM(W23:Y23) -> 1
A24: 2 | B24: 252610270 | C24: Afiq Rizky Ramadhan | D24: L | E24: 0 | F24: 0 | G24: 2 | H24: 0 | I24: 0 | J24: 0 | K24: 0 | L24: 0 | M24: 0 | N24: 0 | O24: 0 | P24: 1 | W24: =SUM(E24,H24,K24,N24,Q24,T24) -> 0 | X24: =SUM(F24,I24,L24,O24,R24,U24) -> 0 | Y24: =SUM(G24,J24,M24,P24,S24,V24) -> 3 | Z24: =SUM(W24:Y24) -> 3
A25: 3 | B25: 252610271 | C25: Ahbi Irwansyah | D25: L | E25: 0 | F25: 0 | G25: 0 | H25: 0 | I25: 0 | J25: 0 | K25: 0 | L25: 0 | M25: 0 | N25: 0 | O25: 0 | P25: 0 | W25: =SUM(E25,H25,K25,N25,Q25,T25) -> 0 | X25: =SUM(F25,I25,L25,O25,R25,U25) -> 0 | Y25: =SUM(G25,J25,M25,P25,S25,V25) -> 0 | Z25: =SUM(W25:Y25) -> 0
A26: 4 | B26: 252610272 | C26: Ahmad Hozali | D26: L | E26: 0 | F26: 0 | G26: 0 | H26: 0 | I26: 0 | J26: 0 | K26: 0 | L26: 0 | M26: 0 | N26: 0 | O26: 0 | P26: 0 | W26: =SUM(E26,H26,K26,N26,Q26,T26) -> 0 | X26: =SUM(F26,I26,L26,O26,R26,U26) -> 0 | Y26: =SUM(G26,J26,M26,P26,S26,V26) -> 0 | Z26: =SUM(W26:Y26) -> 0
A27: 5 | B27: 252610273 | C27: Akbar Maulana | D27: L | E27: 0 | F27: 0 | G27: 0 | H27: 0 | I27: 0 | J27: 0 | K27: 0 | L27: 0 | M27: 0 | N27: 0 | O27: 0 | P27: 0 | W27: =SUM(E27,H27,K27,N27,Q27,T27) -> 0 | X27: =SUM(F27,I27,L27,O27,R27,U27) -> 0 | Y27: =SUM(G27,J27,M27,P27,S27,V27) -> 0 | Z27: =SUM(W27:Y27) -> 0
A28: 6 | B28: 252610274 | C28: Dhalfan Fahry Dwy Fardhana | D28: L | E28: 2 | F28: 0 | G28: 1 | H28: 0 | I28: 0 | J28: 0 | K28: 0 | L28: 0 | M28: 0 | N28: 0 | O28: 0 | P28: 0 | W28: =SUM(E28,H28,K28,N28,Q28,T28) -> 2 | X28: =SUM(F28,I28,L28,O28,R28,U28) -> 0 | Y28: =SUM(G28,J28,M28,P28,S28,V28) -> 1 | Z28: =SUM(W28:Y28) -> 3
A29: 7 | B29: 252610276 | C29: Fadhil Afif Fahdlurrahman | D29: L | E29: 0 | F29: 0 | G29: 0 | H29: 0 | I29: 0 | J29: 0 | K29: 0 | L29: 0 | M29: 0 | N29: 0 | O29: 0 | P29: 0 | W29: =SUM(E29,H29,K29,N29,Q29,T29) -> 0 | X29: =SUM(F29,I29,L29,O29,R29,U29) -> 0 | Y29: =SUM(G29,J29,M29,P29,S29,V29) -> 0 | Z29: =SUM(W29:Y29) -> 0
A30: 8 | B30: 252610277 | C30: Firza Nur Arifin | D30: L | E30: 0 | F30: 0 | G30: 0 | H30: 0 | I30: 0 | J30: 0 | K30: 0 | L30: 0 | M30: 0 | N30: 0 | O30: 0 | P30: 1 | W30: =SUM(E30,H30,K30,N30,Q30,T30) -> 0 | X30: =SUM(F30,I30,L30,O30,R30,U30) -> 0 | Y30: =SUM(G30,J30,M30,P30,S30,V30) -> 1 | Z30: =SUM(W30:Y30) -> 1
A31: 9 | B31: 252610278 | C31: Fitri Yani | D31: P | E31: 0 | F31: 0 | G31: 1 | H31: 0 | I31: 0 | J31: 0 | K31: 1 | L31: 0 | M31: 0 | N31: 0 | O31: 0 | P31: 0 | W31: =SUM(E31,H31,K31,N31,Q31,T31) -> 1 | X31: =SUM(F31,I31,L31,O31,R31,U31) -> 0 | Y31: =SUM(G31,J31,M31,P31,S31,V31) -> 1 | Z31: =SUM(W31:Y31) -> 2
A32: 10 | B32: 252610279 | C32: Haruno Segara Daenova | D32: L | E32: 0 | F32: 0 | G32: 0 | H32: 0 | I32: 0 | J32: 0 | K32: 0 | L32: 0 | M32: 0 | N32: 0 | O32: 0 | P32: 0 | W32: =SUM(E32,H32,K32,N32,Q32,T32) -> 0 | X32: =SUM(F32,I32,L32,O32,R32,U32) -> 0 | Y32: =SUM(G32,J32,M32,P32,S32,V32) -> 0 | Z32: =SUM(W32:Y32) -> 0
A33: 11 | B33: 252610280 | C33: Ilham Aryasatya | D33: L | E33: 1 | F33: 0 | G33: 1 | H33: 0 | I33: 0 | J33: 1 | K33: 1 | L33: 0 | M33: 2 | N33: 0 | O33: 0 | P33: 1 | W33: =SUM(E33,H33,K33,N33,Q33,T33) -> 2 | X33: =SUM(F33,I33,L33,O33,R33,U33) -> 0 | Y33: =SUM(G33,J33,M33,P33,S33,V33) -> 5 | Z33: =SUM(W33:Y33) -> 7
A34: 12 | B34: 252610281 | C34: Johanes Evan Gavrila | D34: L | E34: 2 | F34: 2 | G34: 0 | H34: 0 | I34: 3 | J34: 0 | K34: 0 | L34: 0 | M34: 0 | N34: 0 | O34: 1 | P34: 1 | W34: =SUM(E34,H34,K34,N34,Q34,T34) -> 2 | X34: =SUM(F34,I34,L34,O34,R34,U34) -> 6 | Y34: =SUM(G34,J34,M34,P34,S34,V34) -> 1 | Z34: =SUM(W34:Y34) -> 9
... A58: 36 | B58: 252610306 | C58: Widjayandaru Mustofa | D58: L | E58: 0 | F58: 0 | G58: 0 | H58: 0 | I58: 0 | J58: 0 | K58: 0 | L58: 0 | M58: 0 | N58: 0 | O58: 0 | P58: 0 | W58: =SUM(E58,H58,K58,N58,Q58,T58) -> 0 | X58: =SUM(F58,I58,L58,O58,R58,U58) -> 0 | Y58: =SUM(G58,J58,M58,P58,S58,V58) -> 0 | Z58: =SUM(W58:Y58) -> 0
A59: J U M L AH | E59: ='X TKJ 1'!E60 -> 17 | H59: ='X TKJ 1'!H60 -> 17 | K59: ='X TKJ 1'!K60 -> 13 | N59: ='X TKJ 1'!N60 -> 19 | W59: =SUM(W23:W58) -> 28 | X59: =SUM(X23:X58) -> 23 | Y59: =SUM(Y23:Y58) -> 38 | Z59: =SUM(Z23:Z58) -> 89
P61: Jumlah Ketidakhadiran | W61: =Z59 -> 89
P62: Jmlah Siswa | W62: =A58 -> 36
P63: Presentase Ketidakhadiran | W63: =W61/(W62*W64) -> 0.037457912
P64: Jumlah Hari Efektif | W64: =SUM(E59:V59) -> 66
P65: Presentase Jumlah Kehadiran | W65: =(((W62*W64)-W61)/(W62*W64)) -> 0.96254209
C67: Mengetahui, | U67: ='X TKJ 1'!U68 -> Depok, Juli 2026
C68: Kepala SMK Taruna Bhakti | U68: Wali Kelas / Tingkat
C73: Aina Novera, S.Pd., MM. | U73: Abdul Hamid
C74: NIK. 19710203199510012 | U74: NIK. 19961129201807161

Sheet X TKJ 3
A16: DAFTAR HADIR PESERTA DIDIK SEMESTER GENAP
A17: SMK TARUNA BHAKTI
A18: TAHUN AJARAN 2025/2026
A20: ='X TKJ 1'!A20 -> SEMESTER GENAP | Y20: KELAS/TINGKAT : X TKJ 3
A21: NO | B21: NIPD | C21: NAMA PESERTA DIDIK | D21: JK | E21: JANUARI | H21: FEBRUARI | K21: MARET | N21: APRIL | Q21: MEI | T21: DESEMBER | W21: TOTAL ABSENSI
E22: S | F22: I | G22: A | H22: S | I22: I | J22: A | K22: S | L22: I | M22: A | N22: S | O22: I | P22: A | Q22: S | R22: I | S22: A | T22: S | U22: I | V22: A | W22: S | X22: I | Y22: A | Z22: T
A23: 1 | B23: 252610307 | C23: Adheliya Herdiana | D23: P | E23: 1 | F23: 0 | G23: 0 | H23: 0 | I23: 0 | J23: 0 | K23: 1 | L23: 0 | M23: 0 | N23: 1 | O23: 0 | P23: 0 | W23: =SUM(E23,H23,K23,N23,Q23,T23) -> 3 | X23: =SUM(F23,I23,L23,O23,R23,U23) -> 0 | Y23: =SUM(G23,J23,M23,P23,S23,V23) -> 0 | Z23: =SUM(W23:Y23) -> 3
A24: 2 | B24: 252610308 | C24: Aghis Naela Rahma | D24: P | E24: 2 | F24: 0 | G24: 0 | H24: 0 | I24: 0 | J24: 0 | K24: 0 | L24: 1 | M24: 0 | N24: 0 | O24: 0 | P24: 0 | W24: =SUM(E24,H24,K24,N24,Q24,T24) -> 2 | X24: =SUM(F24,I24,L24,O24,R24,U24) -> 1 | Y24: =SUM(G24,J24,M24,P24,S24,V24) -> 0 | Z24: =SUM(W24:Y24) -> 3
A25: 3 | B25: 252610309 | C25: Althaf Ghailan Prizi | D25: L | E25: 0 | F25: 0 | G25: 0 | H25: 0 | I25: 0 | J25: 0 | K25: 0 | L25: 0 | M25: 0 | N25: 0 | O25: 0 | P25: 0 | W25: =SUM(E25,H25,K25,N25,Q25,T25) -> 0 | X25: =SUM(F25,I25,L25,O25,R25,U25) -> 0 | Y25: =SUM(G25,J25,M25,P25,S25,V25) -> 0 | Z25: =SUM(W25:Y25) -> 0
A26: 4 | B26: 252610310 | C26: Angga Daffarudin | D26: L | E26: 0 | F26: 0 | G26: 0 | H26: 0 | I26: 0 | J26: 0 | K26: 0 | L26: 0 | M26: 0 | N26: 0 | O26: 0 | P26: 0 | W26: =SUM(E26,H26,K26,N26,Q26,T26) -> 0 | X26: =SUM(F26,I26,L26,O26,R26,U26) -> 0 | Y26: =SUM(G26,J26,M26,P26,S26,V26) -> 0 | Z26: =SUM(W26:Y26) -> 0
A27: 5 | B27: 252610311 | C27: Arkan Irhab Nabil | D27: L | E27: 1 | F27: 0 | G27: 0 | H27: 0 | I27: 0 | J27: 0 | K27: 0 | L27: 0 | M27: 0 | N27: 1 | O27: 0 | P27: 0 | W27: =SUM(E27,H27,K27,N27,Q27,T27) -> 2 | X27: =SUM(F27,I27,L27,O27,R27,U27) -> 0 | Y27: =SUM(G27,J27,M27,P27,S27,V27) -> 0 | Z27: =SUM(W27:Y27) -> 2
A28: 6 | B28: 252610312 | C28: Arnold Immanuel Pangaribuan | D28: L | E28: 1 | F28: 0 | G28: 0 | H28: 0 | I28: 0 | J28: 0 | K28: 0 | L28: 0 | M28: 0 | N28: 0 | O28: 0 | P28: 1 | W28: =SUM(E28,H28,K28,N28,Q28,T28) -> 1 | X28: =SUM(F28,I28,L28,O28,R28,U28) -> 0 | Y28: =SUM(G28,J28,M28,P28,S28,V28) -> 1 | Z28: =SUM(W28:Y28) -> 2
A29: 7 | B29: 252610313 | C29: Bagas Heryawan Putra | D29: L | E29: 0 | F29: 0 | G29: 0 | H29: 0 | I29: 0 | J29: 0 | K29: 0 | L29: 0 | M29: 0 | N29: 0 | O29: 0 | P29: 1 | W29: =SUM(E29,H29,K29,N29,Q29,T29) -> 0 | X29: =SUM(F29,I29,L29,O29,R29,U29) -> 0 | Y29: =SUM(G29,J29,M29,P29,S29,V29) -> 1 | Z29: =SUM(W29:Y29) -> 1
A30: 8 | B30: 252610314 | C30: Barakawloh Ibnu Sugianto | D30: L | E30: 1 | F30: 0 | G30: 0 | H30: 0 | I30: 0 | J30: 0 | K30: 1 | L30: 0 | M30: 0 | N30: 0 | O30: 0 | P30: 0 | W30: =SUM(E30,H30,K30,N30,Q30,T30) -> 2 | X30: =SUM(F30,I30,L30,O30,R30,U30) -> 0 | Y30: =SUM(G30,J30,M30,P30,S30,V30) -> 0 | Z30: =SUM(W30:Y30) -> 2
A31: 9 | B31: 252610315 | C31: Bayu Pradana Putra | D31: L | E31: 0 | F31: 0 | G31: 0 | H31: 0 | I31: 0 | J31: 0 | K31: 2 | L31: 0 | M31: 0 | N31: 0 | O31: 0 | P31: 0 | W31: =SUM(E31,H31,K31,N31,Q31,T31) -> 2 | X31: =SUM(F31,I31,L31,O31,R31,U31) -> 0 | Y31: =SUM(G31,J31,M31,P31,S31,V31) -> 0 | Z31: =SUM(W31:Y31) -> 2
A32: 10 | B32: 252610316 | C32: Burhanudin | D32: L | E32: 0 | F32: 0 | G32: 0 | H32: 0 | I32: 0 | J32: 0 | K32: 2 | L32: 0 | M32: 0 | N32: 1 | O32: 0 | P32: 0 | W32: =SUM(E32,H32,K32,N32,Q32,T32) -> 3 | X32: =SUM(F32,I32,L32,O32,R32,U32) -> 0 | Y32: =SUM(G32,J32,M32,P32,S32,V32) -> 0 | Z32: =SUM(W32:Y32) -> 3
A33: 11 | B33: 252610317 | C33: Chiko Pratama Putra Yuliono | D33: L | E33: 0 | F33: 0 | G33: 0 | H33: 0 | I33: 0 | J33: 0 | K33: 0 | L33: 0 | M33: 0 | N33: 1 | O33: 0 | P33: 0 | W33: =SUM(E33,H33,K33,N33,Q33,T33) -> 1 | X33: =SUM(F33,I33,L33,O33,R33,U33) -> 0 | Y33: =SUM(G33,J33,M33,P33,S33,V33) -> 0 | Z33: =SUM(W33:Y33) -> 1
A34: 12 | B34: 252610318 | C34: Dita Permata Sari | D34: P | E34: 0 | F34: 0 | G34: 0 | H34: 0 | I34: 0 | J34: 0 | K34: 0 | L34: 0 | M34: 0 | N34: 0 | O34: 0 | P34: 0 | W34: =SUM(E34,H34,K34,N34,Q34,T34) -> 0 | X34: =SUM(F34,I34,L34,O34,R34,U34) -> 0 | Y34: =SUM(G34,J34,M34,P34,S34,V34) -> 0 | Z34: =SUM(W34:Y34) -> 0
... A60: 38 | B60: 252610344 | C60: Vivi Putri Kinanti | D60: P | E60: 0 | F60: 0 | G60: 0 | H60: 0 | I60: 0 | J60: 0 | K60: 0 | L60: 0 | M60: 0 | N60: 1 | O60: 0 | P60: 0 | W60: =SUM(E60,H60,K60,N60,Q60,T60) -> 1 | X60: =SUM(F60,I60,L60,O60,R60,U60) -> 0 | Y60: =SUM(G60,J60,M60,P60,S60,V60) -> 0 | Z60: =SUM(W60:Y60) -> 1
A61: J U M L AH | E61: ='X TKJ 1'!E60 -> 17 | H61: ='X TKJ 1'!H60 -> 17 | K61: ='X TKJ 1'!K60 -> 13 | N61: ='X TKJ 1'!N60 -> 19 | W61: =SUM(W23:W60) -> 58 | X61: =SUM(X23:X60) -> 5 | Y61: =SUM(Y23:Y60) -> 11 | Z61: =SUM(Z23:Z60) -> 74
P63: Jumlah Ketidakhadiran | W63: =SUM(Z61) -> 74
P64: Jmlah Siswa | W64: =A60 -> 38
P65: Presentase Ketidakhadiran | W65: =W63/(W64*W66) -> 0.029505582
P66: Jumlah Hari Efektif | W66: =SUM(E61:V61) -> 66
P67: Presentase Jumlah Kehadiran | W67: =(((W64*W66)-W63)/(W64*W66)) -> 0.97049442
C69: Mengetahui, | U69: ='X TKJ 1'!U68 -> Depok, Juli 2026
C70: Kepala SMK Taruna Bhakti | U70: Wali Kelas / Tingkat
C75: Aina Novera, S.Pd., MM. | U75: Maesitoh, S.Pd.
C76: NIK. 19710203199510012 | U76: NIK. 19900601201708212

Sheet X TKJ 4
A16: DAFTAR HADIR PESERTA DIDIK SEMESTER GENAP
A17: SMK TARUNA BHAKTI
A18: TAHUN AJARAN 2025/2026
A20: ='X TKJ 1'!A20 -> SEMESTER GENAP | Y20: KELAS/TINGKAT : X TKJ 4
A21: NO | B21: NIPD | C21: NAMA PESERTA DIDIK | D21: JK | E21: JANUARI | H21: FEBRUARI | K21: MARET | N21: APRIL | Q21: MEI | T21: DESEMBER | W21: TOTAL ABSENSI
E22: S | F22: I | G22: A | H22: S | I22: I | J22: A | K22: S | L22: I | M22: A | N22: S | O22: I | P22: A | Q22: S | R22: I | S22: A | T22: S | U22: I | V22: A | W22: S | X22: I | Y22: A | Z22: T
A23: 1 | B23: 252610345 | C23: Adhikal Putra Perkasa | D23: L | E23: 0 | F23: 1 | G23: 0 | H23: 0 | I23: 0 | J23: 0 | K23: 0 | L23: 0 | M23: 1 | N23: 2 | O23: 0 | P23: 0 | W23: =SUM(E23,H23,K23,N23,Q23,T23) -> 2 | X23: =SUM(F23,I23,L23,O23,R23,U23) -> 1 | Y23: =SUM(G23,J23,M23,P23,S23,V23) -> 1 | Z23: =SUM(W23:Y23) -> 4
A24: 2 | B24: 252610346 | C24: Adly Irsyad Hafizh | D24: L | E24: 0 | F24: 1 | G24: 0 | H24: 0 | I24: 0 | J24: 0 | K24: 0 | L24: 0 | M24: 0 | N24: 0 | O24: 0 | P24: 0 | W24: =SUM(E24,H24,K24,N24,Q24,T24) -> 0 | X24: =SUM(F24,I24,L24,O24,R24,U24) -> 1 | Y24: =SUM(G24,J24,M24,P24,S24,V24) -> 0 | Z24: =SUM(W24:Y24) -> 1
A25: 3 | B25: 252610347 | C25: Ahmad Gani | D25: L | E25: 0 | F25: 0 | G25: 1 | H25: 0 | I25: 0 | J25: 0 | K25: 3 | L25: 0 | M25: 0 | N25: 2 | O25: 0 | P25: 1 | W25: =SUM(E25,H25,K25,N25,Q25,T25) -> 5 | X25: =SUM(F25,I25,L25,O25,R25,U25) -> 0 | Y25: =SUM(G25,J25,M25,P25,S25,V25) -> 2 | Z25: =SUM(W25:Y25) -> 7
A26: 4 | B26: 252610348 | C26: Ahmad Riyadi | D26: L | E26: 0 | F26: 0 | G26: 0 | H26: 0 | I26: 0 | J26: 0 | K26: 0 | L26: 0 | M26: 0 | N26: 1 | O26: 0 | P26: 0 | W26: =SUM(E26,H26,K26,N26,Q26,T26) -> 1 | X26: =SUM(F26,I26,L26,O26,R26,U26) -> 0 | Y26: =SUM(G26,J26,M26,P26,S26,V26) -> 0 | Z26: =SUM(W26:Y26) -> 1
A27: 5 | B27: 252610349 | C27: Ahmad Zaidan | D27: L | E27: 1 | F27: 0 | G27: 0 | H27: 0 | I27: 0 | J27: 0 | K27: 0 | L27: 0 | M27: 0 | N27: 1 | O27: 0 | P27: 0 | W27: =SUM(E27,H27,K27,N27,Q27,T27) -> 2 | X27: =SUM(F27,I27,L27,O27,R27,U27) -> 0 | Y27: =SUM(G27,J27,M27,P27,S27,V27) -> 0 | Z27: =SUM(W27:Y27) -> 2
A28: 6 | B28: 252610350 | C28: Aisyah Salsabila Suratno | D28: P | E28: 0 | F28: 0 | G28: 0 | H28: 0 | I28: 0 | J28: 0 | K28: 0 | L28: 0 | M28: 0 | N28: 1 | O28: 0 | P28: 0 | W28: =SUM(E28,H28,K28,N28,Q28,T28) -> 1 | X28: =SUM(F28,I28,L28,O28,R28,U28) -> 0 | Y28: =SUM(G28,J28,M28,P28,S28,V28) -> 0 | Z28: =SUM(W28:Y28) -> 1
A29: 7 | B29: 252610351 | C29: Alfian Putra Budianto | D29: L | E29: 0 | F29: 0 | G29: 0 | H29: 0 | I29: 0 | J29: 0 | K29: 0 | L29: 0 | M29: 0 | N29: 0 | O29: 0 | P29: 0 | W29: =SUM(E29,H29,K29,N29,Q29,T29) -> 0 | X29: =SUM(F29,I29,L29,O29,R29,U29) -> 0 | Y29: =SUM(G29,J29,M29,P29,S29,V29) -> 0 | Z29: =SUM(W29:Y29) -> 0
A30: 8 | B30: 252610352 | C30: Alfinno Oktavian Listianto | D30: L | E30: 0 | F30: 1 | G30: 0 | H30: 0 | I30: 0 | J30: 0 | K30: 0 | L30: 0 | M30: 0 | N30: 1 | O30: 0 | P30: 0 | W30: =SUM(E30,H30,K30,N30,Q30,T30) -> 1 | X30: =SUM(F30,I30,L30,O30,R30,U30) -> 1 | Y30: =SUM(G30,J30,M30,P30,S30,V30) -> 0 | Z30: =SUM(W30:Y30) -> 2
A31: 9 | B31: 252610353 | C31: Alman Rasyid Rizqullah | D31: L | E31: 0 | F31: 0 | G31: 0 | H31: 0 | I31: 0 | J31: 0 | K31: 1 | L31: 0 | M31: 0 | N31: 0 | O31: 0 | P31: 1 | W31: =SUM(E31,H31,K31,N31,Q31,T31) -> 1 | X31: =SUM(F31,I31,L31,O31,R31,U31) -> 0 | Y31: =SUM(G31,J31,M31,P31,S31,V31) -> 1 | Z31: =SUM(W31:Y31) -> 2
A32: 10 | B32: 252610354 | C32: Alvin Setiawan | D32: L | E32: 0 | F32: 0 | G32: 0 | H32: 0 | I32: 0 | J32: 0 | K32: 1 | L32: 0 | M32: 0 | N32: 0 | O32: 0 | P32: 0 | W32: =SUM(E32,H32,K32,N32,Q32,T32) -> 1 | X32: =SUM(F32,I32,L32,O32,R32,U32) -> 0 | Y32: =SUM(G32,J32,M32,P32,S32,V32) -> 0 | Z32: =SUM(W32:Y32) -> 1
A33: 11 | B33: 252610355 | C33: Andrean Hadi Pamungkas | D33: L | E33: 0 | F33: 0 | G33: 0 | H33: 0 | I33: 0 | J33: 0 | K33: 0 | L33: 0 | M33: 0 | N33: 1 | O33: 0 | P33: 0 | W33: =SUM(E33,H33,K33,N33,Q33,T33) -> 1 | X33: =SUM(F33,I33,L33,O33,R33,U33) -> 0 | Y33: =SUM(G33,J33,M33,P33,S33,V33) -> 0 | Z33: =SUM(W33:Y33) -> 1
A34: 12 | B34: 252610356 | C34: Andrew Michael Turnip | D34: L | E34: 0 | F34: 1 | G34: 0 | H34: 1 | I34: 0 | J34: 0 | K34: 0 | L34: 0 | M34: 0 | N34: 0 | O34: 0 | P34: 0 | W34: =SUM(E34,H34,K34,N34,Q34,T34) -> 1 | X34: =SUM(F34,I34,L34,O34,R34,U34) -> 1 | Y34: =SUM(G34,J34,M34,P34,S34,V34) -> 0 | Z34: =SUM(W34:Y34) -> 2
... A60: 38 | B60: 252610382 | C60: Wildhan Ghanyy | D60: L | E60: 0 | F60: 0 | G60: 0 | H60: 0 | I60: 0 | J60: 0 | K60: 0 | L60: 0 | M60: 1 | N60: 0 | O60: 0 | P60: 0 | W60: =SUM(E60,H60,K60,N60,Q60,T60) -> 0 | X60: =SUM(F60,I60,L60,O60,R60,U60) -> 0 | Y60: =SUM(G60,J60,M60,P60,S60,V60) -> 1 | Z60: =SUM(W60:Y60) -> 1
A61: J U M L AH | E61: ='X TKJ 1'!E60 -> 17 | H61: ='X TKJ 1'!H60 -> 17 | K61: ='X TKJ 1'!K60 -> 13 | N61: ='X TKJ 1'!N60 -> 19 | W61: =SUM(W23:W60) -> 44 | X61: =SUM(X23:X60) -> 8 | Y61: =SUM(Y23:Y60) -> 10 | Z61: =SUM(Z23:Z60) -> 62
P63: Jumlah Ketidakhadiran | W63: =SUM(Z61) -> 62
P64: Jmlah Siswa | W64: =A60 -> 38
P65: Presentase Ketidakhadiran | W65: =W63/(W64*W66) -> 0.024720893
P66: Jumlah Hari Efektif | W66: =SUM(E61:V61) -> 66
P67: Presentase Jumlah Kehadiran | W67: =(((W64*W66)-W63)/(W64*W66)) -> 0.97527911
C69: Mengetahui, | U69: ='X TKJ 1'!U68 -> Depok, Juli 2026
C70: Kepala SMK Taruna Bhakti | U70: Wali Kelas / Tingkat
C75: Aina Novera, S.Pd., MM. | U75: Aniek Rochmawati, S.Pd.
C76: NIK. 19710203199510012 | U76: NIK. 19800404201508222

Sheet X ANIMASI 1
A16: DAFTAR HADIR PESERTA DIDIK SEMESTER GENAP
A17: SMK TARUNA BHAKTI
A18: TAHUN AJARAN 2025/2026
A20: ='X TKJ 1'!A20 -> SEMESTER GENAP | Y20: KELAS/TINGKAT : X ANIMASI 1
A21: NO | B21: NIPD | C21: NAMA PESERTA DIDIK | D21: JK | E21: JANUARI | H21: FEBRUARI | K21: MARET | N21: APRIL | Q21: MEI | T21: DESEMBER | W21: TOTAL ABSENSI
E22: S | F22: I | G22: A | H22: S | I22: I | J22: A | K22: S | L22: I | M22: A | N22: S | O22: I | P22: A | Q22: S | R22: I | S22: A | T22: S | U22: I | V22: A | W22: S | X22: I | Y22: A | Z22: T
A23: 1 | B23: 252610490 | C23: Abdul Rabbaniya Hakim | D23: L | E23: 0 | F23: 0 | G23: 0 | H23: 0 | I23: 0 | J23: 0 | K23: 0 | L23: 0 | M23: 0 | N23: 0 | O23: 0 | P23: 0 | W23: =SUM(E23,H23,K23,N23,Q23,T23) -> 0 | X23: =SUM(F23,I23,L23,O23,R23,U23) -> 0 | Y23: =SUM(G23,J23,M23,P23,S23,V23) -> 0 | Z23: =SUM(W23:Y23) -> 0
A24: 2 | B24: 252610491 | C24: Adam Kiran Pratama | D24: L | E24: 0 | F24: 0 | G24: 0 | H24: 0 | I24: 0 | J24: 0 | K24: 0 | L24: 0 | M24: 0 | N24: 0 | O24: 0 | P24: 0 | W24: =SUM(E24,H24,K24,N24,Q24,T24) -> 0 | X24: =SUM(F24,I24,L24,O24,R24,U24) -> 0 | Y24: =SUM(G24,J24,M24,P24,S24,V24) -> 0 | Z24: =SUM(W24:Y24) -> 0
A25: 3 | B25: 252610492 | C25: Ahmad Fauzi Safriayudiansyah | D25: L | E25: 0 | F25: 0 | G25: 0 | H25: 0 | I25: 0 | J25: 0 | K25: 0 | L25: 0 | M25: 0 | N25: 0 | O25: 0 | P25: 0 | W25: =SUM(E25,H25,K25,N25,Q25,T25) -> 0 | X25: =SUM(F25,I25,L25,O25,R25,U25) -> 0 | Y25: =SUM(G25,J25,M25,P25,S25,V25) -> 0 | Z25: =SUM(W25:Y25) -> 0
A26: 4 | B26: 252610493 | C26: Ahmad Lutfi Ramadhan | D26: L | E26: 0 | F26: 0 | G26: 0 | H26: 0 | I26: 0 | J26: 0 | K26: 0 | L26: 0 | M26: 0 | N26: 0 | O26: 0 | P26: 0 | W26: =SUM(E26,H26,K26,N26,Q26,T26) -> 0 | X26: =SUM(F26,I26,L26,O26,R26,U26) -> 0 | Y26: =SUM(G26,J26,M26,P26,S26,V26) -> 0 | Z26: =SUM(W26:Y26) -> 0
A27: 5 | B27: 252610494 | C27: Aisyah Faidah Azmi | D27: P | E27: 0 | F27: 0 | G27: 0 | H27: 0 | I27: 0 | J27: 0 | K27: 0 | L27: 0 | M27: 0 | N27: 0 | O27: 0 | P27: 0 | W27: =SUM(E27,H27,K27,N27,Q27,T27) -> 0 | X27: =SUM(F27,I27,L27,O27,R27,U27) -> 0 | Y27: =SUM(G27,J27,M27,P27,S27,V27) -> 0 | Z27: =SUM(W27:Y27) -> 0
A28: 6 | B28: 252610495 | C28: Alinda Trikusuma Febriyani | D28: P | E28: 0 | F28: 0 | G28: 0 | H28: 0 | I28: 0 | J28: 0 | K28: 0 | L28: 0 | M28: 0 | N28: 0 | O28: 0 | P28: 0 | W28: =SUM(E28,H28,K28,N28,Q28,T28) -> 0 | X28: =SUM(F28,I28,L28,O28,R28,U28) -> 0 | Y28: =SUM(G28,J28,M28,P28,S28,V28) -> 0 | Z28: =SUM(W28:Y28) -> 0
A29: 7 | B29: 252610496 | C29: Bhahiya Atika Fayha | D29: P | E29: 1 | F29: 0 | G29: 0 | H29: 0 | I29: 0 | J29: 0 | K29: 0 | L29: 0 | M29: 0 | N29: 1 | O29: 0 | P29: 0 | W29: =SUM(E29,H29,K29,N29,Q29,T29) -> 2 | X29: =SUM(F29,I29,L29,O29,R29,U29) -> 0 | Y29: =SUM(G29,J29,M29,P29,S29,V29) -> 0 | Z29: =SUM(W29:Y29) -> 2
A30: 8 | B30: 252610497 | C30: Chadrick Frasta Mbotu | D30: L | E30: 0 | F30: 1 | G30: 1 | H30: 0 | I30: 0 | J30: 0 | K30: 0 | L30: 0 | M30: 0 | N30: 0 | O30: 0 | P30: 0 | W30: =SUM(E30,H30,K30,N30,Q30,T30) -> 0 | X30: =SUM(F30,I30,L30,O30,R30,U30) -> 1 | Y30: =SUM(G30,J30,M30,P30,S30,V30) -> 1 | Z30: =SUM(W30:Y30) -> 2
A31: 9 | B31: 252610498 | C31: Cut Ainiya Sakhina Syahlevi | D31: P | E31: 0 | F31: 0 | G31: 0 | H31: 0 | I31: 0 | J31: 0 | K31: 0 | L31: 0 | M31: 0 | N31: 0 | O31: 0 | P31: 0 | W31: =SUM(E31,H31,K31,N31,Q31,T31) -> 0 | X31: =SUM(F31,I31,L31,O31,R31,U31) -> 0 | Y31: =SUM(G31,J31,M31,P31,S31,V31) -> 0 | Z31: =SUM(W31:Y31) -> 0
A32: 10 | B32: 252610499 | C32: Dania Kalya Novita | D32: P | E32: 2 | F32: 0 | G32: 0 | H32: 1 | I32: 0 | J32: 0 | K32: 4 | L32: 0 | M32: 0 | N32: 2 | O32: 0 | P32: 0 | W32: =SUM(E32,H32,K32,N32,Q32,T32) -> 9 | X32: =SUM(F32,I32,L32,O32,R32,U32) -> 0 | Y32: =SUM(G32,J32,M32,P32,S32,V32) -> 0 | Z32: =SUM(W32:Y32) -> 9
A33: 11 | B33: 252610500 | C33: Figo Fadilla | D33: L | E33: 2 | F33: 4 | G33: 0 | H33: 0 | I33: 0 | J33: 0 | K33: 0 | L33: 2 | M33: 0 | N33: 2 | O33: 1 | P33: 0 | W33: =SUM(E33,H33,K33,N33,Q33,T33) -> 4 | X33: =SUM(F33,I33,L33,O33,R33,U33) -> 7 | Y33: =SUM(G33,J33,M33,P33,S33,V33) -> 0 | Z33: =SUM(W33:Y33) -> 11
A34: 12 | B34: 252610501 | C34: Gavin Valerian Fatih | D34: L | E34: 1 | F34: 0 | G34: 0 | H34: 0 | I34: 0 | J34: 0 | K34: 1 | L34: 0 | M34: 0 | N34: 0 | O34: 0 | P34: 0 | W34: =SUM(E34,H34,K34,N34,Q34,T34) -> 2 | X34: =SUM(F34,I34,L34,O34,R34,U34) -> 0 | Y34: =SUM(G34,J34,M34,P34,S34,V34) -> 0 | Z34: =SUM(W34:Y34) -> 2
... A51: 29 | B51: 252610519 | C51: Zhafira Nabila Tamir | D51: P | E51: 3 | F51: 1 | G51: 0 | H51: 0 | I51: 0 | J51: 0 | K51: 0 | L51: 0 | M51: 0 | N51: 0 | O51: 1 | P51: 0 | W51: =SUM(E51,H51,K51,N51,Q51,T51) -> 3 | X51: =SUM(F51,I51,L51,O51,R51,U51) -> 2 | Y51: =SUM(G51,J51,M51,P51,S51,V51) -> 0 | Z51: =SUM(W51:Y51) -> 5
A52: J U M L AH | E52: ='X TKJ 1'!E60 -> 17 | H52: ='X TKJ 1'!H60 -> 17 | K52: ='X TKJ 1'!K60 -> 13 | N52: ='X TKJ 1'!N60 -> 19 | W52: =SUM(W23:W51) -> 44 | X52: =SUM(X23:X51) -> 22 | Y52: =SUM(Y23:Y51) -> 8 | Z52: =SUM(Z23:Z51) -> 74
P54: Jumlah Ketidakhadiran | W54: =Z52 -> 74
P55: Jmlah Siswa | W55: =A51 -> 29
P56: Presentase Ketidakhadiran | W56: =W54/(W55*W57) -> 0.038662487
P57: Jumlah Hari Efektif | W57: =SUM(E52:V52) -> 66
P58: Presentase Jumlah Kehadiran | W58: =(((W55*W57)-W54)/(W55*W57)) -> 0.96133751
C60: Mengetahui, | U60: ='X TKJ 1'!U68 -> Depok, Juli 2026
C61: Kepala SMK Taruna Bhakti | U61: Wali Kelas / Tingkat
C66: Aina Novera, S.Pd., MM. | U66: Gebi Abda Mahes Multazam, S.Pd.I.
C67: NIK. 19710203199510012 | U67: NIK. 19890821201507251

Sheet X ANIMASI 2
A16: DAFTAR HADIR PESERTA DIDIK SEMESTER GENAP
A17: SMK TARUNA BHAKTI
A18: TAHUN AJARAN 2025/2026
A20: ='X TKJ 1'!A20 -> SEMESTER GENAP | Y20: KELAS/TINGKAT : X ANIMASI 2
A21: NO | B21: NIPD | C21: NAMA PESERTA DIDIK | D21: JK | E21: JANUARI | H21: FEBRUARI | K21: MARET | N21: APRIL | Q21: MEI | T21: DESEMBER | W21: TOTAL ABSENSI
E22: S | F22: I | G22: A | H22: S | I22: I | J22: A | K22: S | L22: I | M22: A | N22: S | O22: I | P22: A | Q22: S | R22: I | S22: A | T22: S | U22: I | V22: A | W22: S | X22: I | Y22: A | Z22: T
A23: 1 | B23: 252610520 | C23: Ananda Firmansyah | D23: L | E23: 0 | F23: 0 | G23: 1 | H23: 0 | I23: 0 | J23: 0 | K23: 0 | L23: 0 | M23: 0 | N23: 0 | O23: 0 | P23: 0 | W23: =SUM(E23,H23,K23,N23,Q23,T23) -> 0 | X23: =SUM(F23,I23,L23,O23,R23,U23) -> 0 | Y23: =SUM(G23,J23,M23,P23,S23,V23) -> 1 | Z23: =SUM(W23:Y23) -> 1
A24: 2 | B24: 252610521 | C24: Angelica Gratia Putri Wardono | D24: P | E24: 0 | F24: 0 | G24: 0 | H24: 0 | I24: 0 | J24: 0 | K24: 0 | L24: 0 | M24: 1 | N24: 0 | O24: 0 | P24: 0 | W24: =SUM(E24,H24,K24,N24,Q24,T24) -> 0 | X24: =SUM(F24,I24,L24,O24,R24,U24) -> 0 | Y24: =SUM(G24,J24,M24,P24,S24,V24) -> 1 | Z24: =SUM(W24:Y24) -> 1
A25: 3 | B25: 252610522 | C25: Arga Fatuh Ramadhan | D25: L | E25: 0 | F25: 0 | G25: 1 | H25: 0 | I25: 0 | J25: 0 | K25: 1 | L25: 0 | M25: 0 | N25: 0 | O25: 0 | P25: 1 | W25: =SUM(E25,H25,K25,N25,Q25,T25) -> 1 | X25: =SUM(F25,I25,L25,O25,R25,U25) -> 0 | Y25: =SUM(G25,J25,M25,P25,S25,V25) -> 2 | Z25: =SUM(W25:Y25) -> 3
A26: 4 | B26: 252610523 | C26: Aura Chaterina Purindra | D26: P | E26: 1 | F26: 0 | G26: 0 | H26: 0 | I26: 0 | J26: 0 | K26: 0 | L26: 0 | M26: 0 | N26: 0 | O26: 0 | P26: 0 | W26: =SUM(E26,H26,K26,N26,Q26,T26) -> 1 | X26: =SUM(F26,I26,L26,O26,R26,U26) -> 0 | Y26: =SUM(G26,J26,M26,P26,S26,V26) -> 0 | Z26: =SUM(W26:Y26) -> 1
A27: 5 | B27: 252610524 | C27: Avril Gracia Ananta Then | D27: P | E27: 3 | F27: 0 | G27: 0 | H27: 0 | I27: 0 | J27: 0 | K27: 1 | L27: 0 | M27: 0 | N27: 0 | O27: 0 | P27: 0 | W27: =SUM(E27,H27,K27,N27,Q27,T27) -> 4 | X27: =SUM(F27,I27,L27,O27,R27,U27) -> 0 | Y27: =SUM(G27,J27,M27,P27,S27,V27) -> 0 | Z27: =SUM(W27:Y27) -> 4
A28: 6 | B28: 252610525 | C28: Darrel Gara Pratama | D28: L | E28: 0 | F28: 0 | G28: 0 | H28: 0 | I28: 0 | J28: 0 | K28: 1 | L28: 0 | M28: 0 | N28: 0 | O28: 0 | P28: 0 | W28: =SUM(E28,H28,K28,N28,Q28,T28) -> 1 | X28: =SUM(F28,I28,L28,O28,R28,U28) -> 0 | Y28: =SUM(G28,J28,M28,P28,S28,V28) -> 0 | Z28: =SUM(W28:Y28) -> 1
A29: 7 | B29: 252610526 | C29: Davian Putra Pratama | D29: L | E29: 0 | F29: 0 | G29: 0 | H29: 1 | I29: 0 | J29: 0 | K29: 0 | L29: 0 | M29: 0 | N29: 0 | O29: 0 | P29: 0 | W29: =SUM(E29,H29,K29,N29,Q29,T29) -> 1 | X29: =SUM(F29,I29,L29,O29,R29,U29) -> 0 | Y29: =SUM(G29,J29,M29,P29,S29,V29) -> 0 | Z29: =SUM(W29:Y29) -> 1
A30: 8 | B30: 252610527 | C30: Dimas Kresna Hafizh Suryono | D30: L | E30: 0 | F30: 0 | G30: 0 | H30: 0 | I30: 0 | J30: 0 | K30: 0 | L30: 0 | M30: 0 | N30: 0 | O30: 0 | P30: 0 | W30: =SUM(E30,H30,K30,N30,Q30,T30) -> 0 | X30: =SUM(F30,I30,L30,O30,R30,U30) -> 0 | Y30: =SUM(G30,J30,M30,P30,S30,V30) -> 0 | Z30: =SUM(W30:Y30) -> 0
A31: 9 | B31: 252610528 | C31: Eka Ramadhani Putri | D31: P | E31: 3 | F31: 0 | G31: 0 | H31: 0 | I31: 0 | J31: 0 | K31: 0 | L31: 0 | M31: 0 | N31: 2 | O31: 0 | P31: 0 | W31: =SUM(E31,H31,K31,N31,Q31,T31) -> 5 | X31: =SUM(F31,I31,L31,O31,R31,U31) -> 0 | Y31: =SUM(G31,J31,M31,P31,S31,V31) -> 0 | Z31: =SUM(W31:Y31) -> 5
A32: 10 | B32: 252610529 | C32: Emmanuela Kezia Princessa Huwae | D32: P | E32: 0 | F32: 0 | G32: 0 | H32: 0 | I32: 0 | J32: 0 | K32: 1 | L32: 0 | M32: 0 | N32: 3 | O32: 0 | P32: 0 | W32: =SUM(E32,H32,K32,N32,Q32,T32) -> 4 | X32: =SUM(F32,I32,L32,O32,R32,U32) -> 0 | Y32: =SUM(G32,J32,M32,P32,S32,V32) -> 0 | Z32: =SUM(W32:Y32) -> 4
A33: 11 | B33: 252610530 | C33: M. Alif Ar Rifai | D33: L | E33: 0 | F33: 0 | G33: 0 | H33: 0 | I33: 0 | J33: 0 | K33: 0 | L33: 0 | M33: 0 | N33: 0 | O33: 0 | P33: 1 | W33: =SUM(E33,H33,K33,N33,Q33,T33) -> 0 | X33: =SUM(F33,I33,L33,O33,R33,U33) -> 0 | Y33: =SUM(G33,J33,M33,P33,S33,V33) -> 1 | Z33: =SUM(W33:Y33) -> 1
A34: 12 | B34: 252610531 | C34: M. Hafidz N | D34: L | E34: 0 | F34: 0 | G34: 0 | H34: 0 | I34: 0 | J34: 0 | K34: 1 | L34: 0 | M34: 0 | N34: 0 | O34: 0 | P34: 0 | W34: =SUM(E34,H34,K34,N34,Q34,T34) -> 1 | X34: =SUM(F34,I34,L34,O34,R34,U34) -> 0 | Y34: =SUM(G34,J34,M34,P34,S34,V34) -> 0 | Z34: =SUM(W34:Y34) -> 1
... A51: 29 | B51: 252610548 | C51: Zahra Nur Maulida | D51: P | E51: 0 | F51: 0 | G51: 0 | H51: 1 | I51: 0 | J51: 0 | K51: 0 | L51: 0 | M51: 0 | N51: 2 | O51: 0 | P51: 0 | W51: =SUM(E51,H51,K51,N51,Q51,T51) -> 3 | X51: =SUM(F51,I51,L51,O51,R51,U51) -> 0 | Y51: =SUM(G51,J51,M51,P51,S51,V51) -> 0 | Z51: =SUM(W51:Y51) -> 3
A52: J U M L AH | E52: ='X TKJ 1'!E60 -> 17 | H52: ='X TKJ 1'!H60 -> 17 | K52: ='X TKJ 1'!K60 -> 13 | N52: ='X TKJ 1'!N60 -> 19 | W52: =SUM(W23:W51) -> 51 | X52: =SUM(X23:X51) -> 5 | Y52: =SUM(Y23:Y51) -> 13 | Z52: =SUM(Z23:Z51) -> 69
P54: Jumlah Ketidakhadiran | W54: =Z52 -> 69
P55: Jmlah Siswa | W55: =A51 -> 29
P56: Presentase Ketidakhadiran | W56: =W54/(W55*W57) -> 0.036050157
P57: Jumlah Hari Efektif | W57: =SUM(E52:V52) -> 66
P58: Presentase Jumlah Kehadiran | W58: =(((W55*W57)-W54)/(W55*W57)) -> 0.96394984
C60: Mengetahui, | U60: ='X TKJ 1'!U68 -> Depok, Juli 2026
C61: Kepala SMK Taruna Bhakti | U61: Wali Kelas / Tingkat
C66: Aina Novera, S.Pd., MM. | U66: Yulfani Wulan Maulita, S.Ds.
C67: NIK. 19710203199510012 | U67: NIK. 19940807201907152

Sheet X TEI
A16: DAFTAR HADIR PESERTA DIDIK SEMESTER GENAP
A17: SMK TARUNA BHAKTI
A18: TAHUN AJARAN 2025/2026
A20: ='X TKJ 1'!A20 -> SEMESTER GENAP | Y20: KELAS/TINGKAT : X TEI
A21: NO | B21: NIPD | C21: NAMA PESERTA DIDIK | D21: JK | E21: JANUARI | H21: FEBRUARI | K21: MARET | N21: APRIL | Q21: MEI | T21: DESEMBER | W21: TOTAL ABSENSI
E22: S | F22: I | G22: A | H22: S | I22: I | J22: A | K22: S | L22: I | M22: A | N22: S | O22: I | P22: A | Q22: S | R22: I | S22: A | T22: S | U22: I | V22: A | W22: S | X22: I | Y22: A | Z22: T
A23: 1 | B23: 252610001 | C23: Adrian Faridz Achmad | D23: L | E23: 0 | F23: 0 | G23: 0 | H23: 0 | I23: 0 | J23: 0 | K23: 1 | L23: 0 | M23: 0 | N23: 0 | O23: 1 | P23: 0 | W23: =SUM(E23,H23,K23,N23,Q23,T23) -> 1 | X23: =SUM(F23,I23,L23,O23,R23,U23) -> 1 | Y23: =SUM(G23,J23,M23,P23,S23,V23) -> 0 | Z23: =SUM(W23:Y23) -> 2
A24: 2 | B24: 252610002 | C24: Ahmad Bagas Pratama | D24: L | E24: 1 | F24: 0 | G24: 0 | H24: 0 | I24: 0 | J24: 0 | K24: 0 | L24: 0 | M24: 0 | N24: 0 | O24: 0 | P24: 0 | W24: =SUM(E24,H24,K24,N24,Q24,T24) -> 1 | X24: =SUM(F24,I24,L24,O24,R24,U24) -> 0 | Y24: =SUM(G24,J24,M24,P24,S24,V24) -> 0 | Z24: =SUM(W24:Y24) -> 1
A25: 3 | B25: 252610003 | C25: Ahmad Fazlleka | D25: L | E25: 1 | F25: 0 | G25: 0 | H25: 0 | I25: 0 | J25: 0 | K25: 0 | L25: 1 | M25: 0 | N25: 0 | O25: 0 | P25: 0 | W25: =SUM(E25,H25,K25,N25,Q25,T25) -> 1 | X25: =SUM(F25,I25,L25,O25,R25,U25) -> 1 | Y25: =SUM(G25,J25,M25,P25,S25,V25) -> 0 | Z25: =SUM(W25:Y25) -> 2
A26: 4 | B26: 252610004 | C26: Ahmad Hadzami S | D26: L | E26: 0 | F26: 0 | G26: 0 | H26: 0 | I26: 0 | J26: 0 | K26: 0 | L26: 0 | M26: 0 | N26: 0 | O26: 0 | P26: 0 | W26: =SUM(E26,H26,K26,N26,Q26,T26) -> 0 | X26: =SUM(F26,I26,L26,O26,R26,U26) -> 0 | Y26: =SUM(G26,J26,M26,P26,S26,V26) -> 0 | Z26: =SUM(W26:Y26) -> 0
A27: 5 | B27: 252610005 | C27: Akbar Maulana | D27: L | E27: 0 | F27: 0 | G27: 0 | H27: 0 | I27: 0 | J27: 0 | K27: 0 | L27: 0 | M27: 0 | N27: 0 | O27: 0 | P27: 0 | W27: =SUM(E27,H27,K27,N27,Q27,T27) -> 0 | X27: =SUM(F27,I27,L27,O27,R27,U27) -> 0 | Y27: =SUM(G27,J27,M27,P27,S27,V27) -> 0 | Z27: =SUM(W27:Y27) -> 0
A28: 6 | B28: 252610006 | C28: Akbar Putra Manggala | D28: L | E28: 0 | F28: 0 | G28: 0 | H28: 0 | I28: 0 | J28: 0 | K28: 0 | L28: 0 | M28: 0 | N28: 0 | O28: 0 | P28: 0 | W28: =SUM(E28,H28,K28,N28,Q28,T28) -> 0 | X28: =SUM(F28,I28,L28,O28,R28,U28) -> 0 | Y28: =SUM(G28,J28,M28,P28,S28,V28) -> 0 | Z28: =SUM(W28:Y28) -> 0
A29: 7 | B29: 252610007 | C29: Al Fath January Babussalam | D29: L | E29: 0 | F29: 0 | G29: 0 | H29: 1 | I29: 0 | J29: 0 | K29: 0 | L29: 0 | M29: 0 | N29: 0 | O29: 0 | P29: 0 | W29: =SUM(E29,H29,K29,N29,Q29,T29) -> 1 | X29: =SUM(F29,I29,L29,O29,R29,U29) -> 0 | Y29: =SUM(G29,J29,M29,P29,S29,V29) -> 0 | Z29: =SUM(W29:Y29) -> 1
A30: 8 | B30: 252610008 | C30: Devin Eistein Siswanto | D30: L | E30: 1 | F30: 0 | G30: 0 | H30: 0 | I30: 0 | J30: 0 | K30: 0 | L30: 0 | M30: 0 | N30: 0 | O30: 0 | P30: 0 | W30: =SUM(E30,H30,K30,N30,Q30,T30) -> 1 | X30: =SUM(F30,I30,L30,O30,R30,U30) -> 0 | Y30: =SUM(G30,J30,M30,P30,S30,V30) -> 0 | Z30: =SUM(W30:Y30) -> 1
A31: 9 | B31: 252610009 | C31: Erik Setiawan | D31: L | E31: 0 | F31: 0 | G31: 0 | H31: 0 | I31: 0 | J31: 0 | K31: 0 | L31: 0 | M31: 0 | N31: 1 | O31: 0 | P31: 0 | W31: =SUM(E31,H31,K31,N31,Q31,T31) -> 1 | X31: =SUM(F31,I31,L31,O31,R31,U31) -> 0 | Y31: =SUM(G31,J31,M31,P31,S31,V31) -> 0 | Z31: =SUM(W31:Y31) -> 1
A32: 10 | B32: 252610010 | C32: Fadli Firman Arifin | D32: L | E32: 0 | F32: 1 | G32: 0 | H32: 0 | I32: 0 | J32: 0 | K32: 1 | L32: 0 | M32: 0 | N32: 0 | O32: 0 | P32: 0 | W32: =SUM(E32,H32,K32,N32,Q32,T32) -> 1 | X32: =SUM(F32,I32,L32,O32,R32,U32) -> 1 | Y32: =SUM(G32,J32,M32,P32,S32,V32) -> 0 | Z32: =SUM(W32:Y32) -> 2
A33: 11 | B33: 252610011 | C33: Fahrenza Ahmad Fathan | D33: L | E33: 1 | F33: 0 | G33: 0 | H33: 0 | I33: 0 | J33: 0 | K33: 0 | L33: 0 | M33: 1 | N33: 0 | O33: 0 | P33: 0 | W33: =SUM(E33,H33,K33,N33,Q33,T33) -> 1 | X33: =SUM(F33,I33,L33,O33,R33,U33) -> 0 | Y33: =SUM(G33,J33,M33,P33,S33,V33) -> 1 | Z33: =SUM(W33:Y33) -> 2
A34: 12 | B34: 252610012 | C34: Fathimah | D34: P | E34: 1 | F34: 0 | G34: 1 | H34: 0 | I34: 0 | J34: 0 | K34: 1 | L34: 0 | M34: 0 | N34: 2 | O34: 0 | P34: 0 | W34: =SUM(E34,H34,K34,N34,Q34,T34) -> 4 | X34: =SUM(F34,I34,L34,O34,R34,U34) -> 0 | Y34: =SUM(G34,J34,M34,P34,S34,V34) -> 1 | Z34: =SUM(W34:Y34) -> 5
... A68: 46 | B68: 252610085 | C68: Ahmad Bayhaqi | D68: L | E68: 0 | F68: 0 | G68: 0 | H68: 0 | I68: 0 | J68: 0 | K68: 0 | L68: 0 | M68: 1 | N68: 0 | O68: 0 | P68: 0 | W68: =SUM(E68,H68,K68,N68,Q68,T68) -> 0 | X68: =SUM(F68,I68,L68,O68,R68,U68) -> 0 | Y68: =SUM(G68,J68,M68,P68,S68,V68) -> 1 | Z68: =SUM(W68:Y68) -> 1
A69: J U M L AH | E69: ='X TKJ 1'!E60 -> 17 | H69: ='X TKJ 1'!H60 -> 17 | K69: ='X TKJ 1'!K60 -> 13 | N69: ='X TKJ 1'!N60 -> 19 | W69: =SUM(W23:W68) -> 50 | X69: =SUM(X23:X68) -> 19 | Y69: =SUM(Y23:Y68) -> 45 | Z69: =SUM(Z23:Z68) -> 114
P71: Jumlah Ketidakhadiran | W71: =SUM(Z69) -> 114
P72: Jmlah Siswa | W72: =A68 -> 46
P73: Presentase Ketidakhadiran | W73: =W71/(W72*W74) -> 0.037549407
P74: Jumlah Hari Efektif | W74: =SUM(E69:V69) -> 66
P75: Presentase Jumlah Kehadiran | W75: =(((W72*W74)-W71)/(W72*W74)) -> 0.96245059
C77: Mengetahui, | U77: ='X TKJ 1'!U68 -> Depok, Juli 2026
C78: Kepala SMK Taruna Bhakti | U78: Wali Kelas / Tingkat
C83: Aina Novera, S.Pd., MM. | U83: Mahran Mawarid, S, Pd.
C84: NIK. 19710203199510012 | U84: NIK. 20020512202408011

Sheet X PSPT 1
A16: DAFTAR HADIR PESERTA DIDIK SEMESTER GENAP
A17: SMK TARUNA BHAKTI
A18: TAHUN AJARAN 2025/2026
A20: ='X TKJ 1'!A20 -> SEMESTER GENAP | Y20: KELAS/TINGKAT : X PSPT 1
A21: NO | B21: NIPD | C21: NAMA PESERTA DIDIK | D21: JK | E21: JANUARI | H21: FEBRUARI | K21: MARET | N21: APRIL | Q21: MEI | T21: DESEMBER | W21: TOTAL ABSENSI
E22: S | F22: I | G22: A | H22: S | I22: I | J22: A | K22: S | L22: I | M22: A | N22: S | O22: I | P22: A | Q22: S | R22: I | S22: A | T22: S | U22: I | V22: A | W22: S | X22: I | Y22: A | Z22: T
A23: 1 | B23: 252610383 | C23: Aira Putri Utami | D23: P | E23: 1 | F23: 0 | G23: 0 | H23: 0 | I23: 0 | J23: 0 | K23: 0 | L23: 0 | M23: 0 | N23: 1 | O23: 0 | P23: 0 | W23: =SUM(E23,H23,K23,N23,Q23,T23) -> 2 | X23: =SUM(F23,I23,L23,O23,R23,U23) -> 0 | Y23: =SUM(G23,J23,M23,P23,S23,V23) -> 0 | Z23: =SUM(W23:Y23) -> 2
A24: 2 | B24: 252610384 | C24: Alkais Gilang Ramadhan | D24: L | E24: 0 | F24: 0 | G24: 0 | H24: 0 | I24: 0 | J24: 0 | K24: 0 | L24: 0 | M24: 0 | N24: 0 | O24: 0 | P24: 0 | W24: =SUM(E24,H24,K24,N24,Q24,T24) -> 0 | X24: =SUM(F24,I24,L24,O24,R24,U24) -> 0 | Y24: =SUM(G24,J24,M24,P24,S24,V24) -> 0 | Z24: =SUM(W24:Y24) -> 0
A25: 3 | B25: 252610385 | C25: Alva Rizki Aldi Andriansyah | D25: L | E25: 0 | F25: 0 | G25: 0 | H25: 0 | I25: 0 | J25: 0 | K25: 0 | L25: 0 | M25: 0 | N25: 0 | O25: 0 | P25: 0 | W25: =SUM(E25,H25,K25,N25,Q25,T25) -> 0 | X25: =SUM(F25,I25,L25,O25,R25,U25) -> 0 | Y25: =SUM(G25,J25,M25,P25,S25,V25) -> 0 | Z25: =SUM(W25:Y25) -> 0
A26: 4 | B26: 252610386 | C26: Alya Aqeela Rivaldi | D26: P | E26: 2 | F26: 0 | G26: 0 | H26: 0 | I26: 0 | J26: 0 | K26: 1 | L26: 0 | M26: 0 | N26: 1 | O26: 0 | P26: 0 | W26: =SUM(E26,H26,K26,N26,Q26,T26) -> 4 | X26: =SUM(F26,I26,L26,O26,R26,U26) -> 0 | Y26: =SUM(G26,J26,M26,P26,S26,V26) -> 0 | Z26: =SUM(W26:Y26) -> 4
A27: 5 | B27: 252610387 | C27: Alyana Rahma | D27: P | E27: 0 | F27: 0 | G27: 0 | H27: 0 | I27: 0 | J27: 0 | K27: 0 | L27: 0 | M27: 0 | N27: 1 | O27: 0 | P27: 0 | W27: =SUM(E27,H27,K27,N27,Q27,T27) -> 1 | X27: =SUM(F27,I27,L27,O27,R27,U27) -> 0 | Y27: =SUM(G27,J27,M27,P27,S27,V27) -> 0 | Z27: =SUM(W27:Y27) -> 1
A28: 6 | B28: 252610388 | C28: Aqilla Aurelia Safari | D28: P | E28: 0 | F28: 0 | G28: 0 | H28: 0 | I28: 0 | J28: 0 | K28: 1 | L28: 0 | M28: 0 | N28: 0 | O28: 0 | P28: 0 | W28: =SUM(E28,H28,K28,N28,Q28,T28) -> 1 | X28: =SUM(F28,I28,L28,O28,R28,U28) -> 0 | Y28: =SUM(G28,J28,M28,P28,S28,V28) -> 0 | Z28: =SUM(W28:Y28) -> 1
A29: 7 | B29: 252610389 | C29: Arumi Sandy Alenita Putri | D29: P | E29: 0 | F29: 0 | G29: 0 | H29: 0 | I29: 0 | J29: 0 | K29: 0 | L29: 0 | M29: 0 | N29: 0 | O29: 0 | P29: 0 | W29: =SUM(E29,H29,K29,N29,Q29,T29) -> 0 | X29: =SUM(F29,I29,L29,O29,R29,U29) -> 0 | Y29: =SUM(G29,J29,M29,P29,S29,V29) -> 0 | Z29: =SUM(W29:Y29) -> 0
A30: 8 | B30: 252610390 | C30: Bong Eriko | D30: L | E30: 2 | F30: 0 | G30: 0 | H30: 1 | I30: 0 | J30: 0 | K30: 1 | L30: 0 | M30: 0 | N30: 3 | O30: 0 | P30: 0 | W30: =SUM(E30,H30,K30,N30,Q30,T30) -> 7 | X30: =SUM(F30,I30,L30,O30,R30,U30) -> 0 | Y30: =SUM(G30,J30,M30,P30,S30,V30) -> 0 | Z30: =SUM(W30:Y30) -> 7
A31: 9 | B31: 252610391 | C31: Chika Anastasya | D31: P | E31: 0 | F31: 0 | G31: 0 | H31: 0 | I31: 0 | J31: 0 | K31: 0 | L31: 0 | M31: 0 | N31: 0 | O31: 0 | P31: 0 | W31: =SUM(E31,H31,K31,N31,Q31,T31) -> 0 | X31: =SUM(F31,I31,L31,O31,R31,U31) -> 0 | Y31: =SUM(G31,J31,M31,P31,S31,V31) -> 0 | Z31: =SUM(W31:Y31) -> 0
A32: 10 | B32: 252610392 | C32: Dea Almaira Suryanto | D32: P | E32: 0 | F32: 0 | G32: 0 | H32: 0 | I32: 1 | J32: 0 | K32: 0 | L32: 0 | M32: 0 | N32: 0 | O32: 0 | P32: 0 | W32: =SUM(E32,H32,K32,N32,Q32,T32) -> 0 | X32: =SUM(F32,I32,L32,O32,R32,U32) -> 1 | Y32: =SUM(G32,J32,M32,P32,S32,V32) -> 0 | Z32: =SUM(W32:Y32) -> 1
A33: 11 | B33: 252610393 | C33: Denis Ibrahim | D33: L | E33: 2 | F33: 0 | G33: 1 | H33: 0 | I33: 0 | J33: 0 | K33: 1 | L33: 0 | M33: 0 | N33: 2 | O33: 0 | P33: 1 | W33: =SUM(E33,H33,K33,N33,Q33,T33) -> 5 | X33: =SUM(F33,I33,L33,O33,R33,U33) -> 0 | Y33: =SUM(G33,J33,M33,P33,S33,V33) -> 2 | Z33: =SUM(W33:Y33) -> 7
A34: 12 | B34: 252610394 | C34: Fahaz Arga Ramadhan | D34: L | E34: 2 | F34: 0 | G34: 0 | H34: 0 | I34: 0 | J34: 0 | K34: 1 | L34: 0 | M34: 1 | N34: 1 | O34: 0 | P34: 1 | W34: =SUM(E34,H34,K34,N34,Q34,T34) -> 4 | X34: =SUM(F34,I34,L34,O34,R34,U34) -> 0 | Y34: =SUM(G34,J34,M34,P34,S34,V34) -> 2 | Z34: =SUM(W34:Y34) -> 6
... A58: 36 | B58: 252610455 | C58: Andisa Kirana | D58: P | E58: 0 | F58: 0 | G58: 0 | H58: 0 | I58: 0 | J58: 0 | K58: 0 | L58: 0 | M58: 1 | N58: 0 | O58: 0 | P58: 0 | W58: =SUM(E58,H58,K58,N58,Q58,T58) -> 0 | X58: =SUM(F58,I58,L58,O58,R58,U58) -> 0 | Y58: =SUM(G58,J58,M58,P58,S58,V58) -> 1 | Z58: =SUM(W58:Y58) -> 1
A59: J U M L AH | E59: ='X TKJ 1'!E60 -> 17 | H59: ='X TKJ 1'!H60 -> 17 | K59: ='X TKJ 1'!K60 -> 13 | N59: ='X TKJ 1'!N60 -> 19 | W59: =SUM(W23:W58) -> 56 | X59: =SUM(X23:X58) -> 8 | Y59: =SUM(Y23:Y58) -> 17 | Z59: =SUM(Z23:Z58) -> 81
P61: Jumlah Ketidakhadiran | W61: =SUM(Z59) -> 81
P62: Jmlah Siswa | W62: =A58 -> 36
P63: Presentase Ketidakhadiran | W63: =W61/(W62*W64) -> 0.034090909
P64: Jumlah Hari Efektif | W64: =SUM(E59:V59) -> 66
P65: Presentase Jumlah Kehadiran | W65: =(((W62*W64)-W61)/(W62*W64)) -> 0.96590909
C67: Mengetahui, | U67: ='X TKJ 1'!U68 -> Depok, Juli 2026
C68: Kepala SMK Taruna Bhakti | U68: Wali Kelas / Tingkat
C73: Aina Novera, S.Pd., MM. | U73: Nur Syafitri, S.I.Kom.
C74: NIK. 19710203199510012 | U74: NIK. 19940630201607232

Sheet X PSPT 2
A16: DAFTAR HADIR PESERTA DIDIK SEMESTER GENAP
A17: SMK TARUNA BHAKTI
A18: TAHUN AJARAN 2025/2026
A20: ='X TKJ 1'!A20 -> SEMESTER GENAP | Y20: KELAS/TINGKAT : X PSPT 2
A21: NO | B21: NIPD | C21: NAMA PESERTA DIDIK | D21: JK | E21: JANUARI | H21: FEBRUARI | K21: MARET | N21: APRIL | Q21: MEI | T21: DESEMBER | W21: TOTAL ABSENSI
E22: S | F22: I | G22: A | H22: S | I22: I | J22: A | K22: S | L22: I | M22: A | N22: S | O22: I | P22: A | Q22: S | R22: I | S22: A | T22: S | U22: I | V22: A | W22: S | X22: I | Y22: A | Z22: T
A23: 1 | B23: 252610418 | C23: Abdul Malik Adil Derajat | D23: L | E23: 0 | F23: 0 | G23: 1 | H23: 0 | I23: 0 | J23: 0 | K23: 1 | L23: 0 | M23: 2 | N23: 0 | O23: 0 | P23: 1 | W23: =SUM(E23,H23,K23,N23,Q23,T23) -> 1 | X23: =SUM(F23,I23,L23,O23,R23,U23) -> 0 | Y23: =SUM(G23,J23,M23,P23,S23,V23) -> 4 | Z23: =SUM(W23:Y23) -> 5
A24: 2 | B24: 252610419 | C24: Abelia Maedy Putri | D24: P | E24: 2 | F24: 0 | G24: 0 | H24: 0 | I24: 0 | J24: 0 | K24: 1 | L24: 0 | M24: 0 | N24: 0 | O24: 0 | P24: 0 | W24: =SUM(E24,H24,K24,N24,Q24,T24) -> 3 | X24: =SUM(F24,I24,L24,O24,R24,U24) -> 0 | Y24: =SUM(G24,J24,M24,P24,S24,V24) -> 0 | Z24: =SUM(W24:Y24) -> 3
A25: 3 | B25: 252610420 | C25: Ade Bunga Oktaniry | D25: P | E25: 0 | F25: 0 | G25: 0 | H25: 0 | I25: 0 | J25: 0 | K25: 0 | L25: 0 | M25: 0 | N25: 1 | O25: 0 | P25: 0 | W25: =SUM(E25,H25,K25,N25,Q25,T25) -> 1 | X25: =SUM(F25,I25,L25,O25,R25,U25) -> 0 | Y25: =SUM(G25,J25,M25,P25,S25,V25) -> 0 | Z25: =SUM(W25:Y25) -> 1
A26: 4 | B26: 252610421 | C26: Adhiva Jihan Addina | D26: P | E26: 0 | F26: 0 | G26: 0 | H26: 0 | I26: 0 | J26: 0 | K26: 1 | L26: 0 | M26: 0 | N26: 1 | O26: 0 | P26: 0 | W26: =SUM(E26,H26,K26,N26,Q26,T26) -> 2 | X26: =SUM(F26,I26,L26,O26,R26,U26) -> 0 | Y26: =SUM(G26,J26,M26,P26,S26,V26) -> 0 | Z26: =SUM(W26:Y26) -> 2
A27: 5 | B27: 252610422 | C27: Aira Kevania Purindra | D27: P | E27: 0 | F27: 0 | G27: 0 | H27: 0 | I27: 0 | J27: 0 | K27: 1 | L27: 0 | M27: 0 | N27: 4 | O27: 0 | P27: 0 | W27: =SUM(E27,H27,K27,N27,Q27,T27) -> 5 | X27: =SUM(F27,I27,L27,O27,R27,U27) -> 0 | Y27: =SUM(G27,J27,M27,P27,S27,V27) -> 0 | Z27: =SUM(W27:Y27) -> 5
B28: 252610424 | C28: Avrillya Azzahra | D28: P | E28: 1 | F28: 0 | G28: 4 | H28: 0 | I28: 0 | J28: 1 | K28: 1 | L28: 0 | M28: 2 | N28: 1 | O28: 0 | P28: 6 | W28: =SUM(E28,H28,K28,N28,Q28,T28) -> 3 | X28: =SUM(F28,I28,L28,O28,R28,U28) -> 0 | Y28: =SUM(G28,J28,M28,P28,S28,V28) -> 13 | Z28: =SUM(W28:Y28) -> 16
A29: 6 | B29: 252610425 | C29: Benedikta Anezka Vigiyantari | D29: P | E29: 0 | F29: 0 | G29: 0 | H29: 0 | I29: 0 | J29: 0 | K29: 0 | L29: 2 | M29: 0 | N29: 0 | O29: 0 | P29: 0 | W29: =SUM(E29,H29,K29,N29,Q29,T29) -> 0 | X29: =SUM(F29,I29,L29,O29,R29,U29) -> 2 | Y29: =SUM(G29,J29,M29,P29,S29,V29) -> 0 | Z29: =SUM(W29:Y29) -> 2
A30: 7 | B30: 252610426 | C30: Devina Primantika Sari | D30: P | E30: 1 | F30: 0 | G30: 0 | H30: 0 | I30: 0 | J30: 0 | K30: 1 | L30: 1 | M30: 0 | N30: 0 | O30: 1 | P30: 0 | W30: =SUM(E30,H30,K30,N30,Q30,T30) -> 2 | X30: =SUM(F30,I30,L30,O30,R30,U30) -> 2 | Y30: =SUM(G30,J30,M30,P30,S30,V30) -> 0 | Z30: =SUM(W30:Y30) -> 4
A31: 8 | B31: 252610427 | C31: Dewi Aira | D31: P | E31: 0 | F31: 0 | G31: 0 | H31: 0 | I31: 0 | J31: 0 | K31: 0 | L31: 0 | M31: 0 | N31: 0 | O31: 0 | P31: 1 | W31: =SUM(E31,H31,K31,N31,Q31,T31) -> 0 | X31: =SUM(F31,I31,L31,O31,R31,U31) -> 0 | Y31: =SUM(G31,J31,M31,P31,S31,V31) -> 1 | Z31: =SUM(W31:Y31) -> 1
A32: 9 | B32: 252610428 | C32: Faiz Nadhir Musafa | D32: L | E32: 0 | F32: 0 | G32: 0 | H32: 0 | I32: 0 | J32: 0 | K32: 0 | L32: 0 | M32: 0 | N32: 0 | O32: 0 | P32: 0 | W32: =SUM(E32,H32,K32,N32,Q32,T32) -> 0 | X32: =SUM(F32,I32,L32,O32,R32,U32) -> 0 | Y32: =SUM(G32,J32,M32,P32,S32,V32) -> 0 | Z32: =SUM(W32:Y32) -> 0
A33: 10 | B33: 252610429 | C33: Farel Elmaurel | D33: L | E33: 0 | F33: 0 | G33: 0 | H33: 0 | I33: 0 | J33: 0 | K33: 0 | L33: 0 | M33: 0 | N33: 0 | O33: 0 | P33: 0 | W33: =SUM(E33,H33,K33,N33,Q33,T33) -> 0 | X33: =SUM(F33,I33,L33,O33,R33,U33) -> 0 | Y33: =SUM(G33,J33,M33,P33,S33,V33) -> 0 | Z33: =SUM(W33:Y33) -> 0
A34: 11 | B34: 252610430 | C34: Fazrin Fadhillah Akbhar | D34: L | E34: 2 | F34: 0 | G34: 1 | H34: 0 | I34: 0 | J34: 1 | K34: 0 | L34: 1 | M34: 1 | N34: 1 | O34: 1 | P34: 2 | W34: =SUM(E34,H34,K34,N34,Q34,T34) -> 3 | X34: =SUM(F34,I34,L34,O34,R34,U34) -> 2 | Y34: =SUM(G34,J34,M34,P34,S34,V34) -> 5 | Z34: =SUM(W34:Y34) -> 10
A35: 12 | B35: 252610431 | C35: Haikal Okto Messi | D35: L | E35: 0 | F35: 0 | G35: 0 | H35: 0 | I35: 0 | J35: 0 | K35: 0 | L35: 0 | M35: 0 | N35: 0 | O35: 0 | P35: 0 | W35: =SUM(E35,H35,K35,N35,Q35,T35) -> 0 | X35: =SUM(F35,I35,L35,O35,R35,U35) -> 0 | Y35: =SUM(G35,J35,M35,P35,S35,V35) -> 0 | Z35: =SUM(W35:Y35) -> 0
A36: 13 | B36: 252610432 | C36: Imam Ediyanto | D36: L | E36: 1 | F36: 0 | G36: 0 | H36: 0 | I36: 0 | J36: 0 | K36: 0 | L36: 0 | M36: 0 | N36: 0 | O36: 0 | P36: 0 | W36: =SUM(E36,H36,K36,N36,Q36,T36) -> 1 | X36: =SUM(F36,I36,L36,O36,R36,U36) -> 0 | Y36: =SUM(G36,J36,M36,P36,S36,V36) -> 0 | Z36: =SUM(W36:Y36) -> 1
A37: 14 | B37: 252610433 | C37: Indah Afandi | D37: P | E37: 0 | F37: 0 | G37: 0 | H37: 0 | I37: 0 | J37: 0 | K37: 0 | L37: 0 | M37: 0 | N37: 0 | O37: 0 | P37: 0 | W37: =SUM(E37,H37,K37,N37,Q37,T37) -> 0 | X37: =SUM(F37,I37,L37,O37,R37,U37) -> 0 | Y37: =SUM(G37,J37,M37,P37,S37,V37) -> 0 | Z37: =SUM(W37:Y37) -> 0
A38: 15 | B38: 252610434 | C38: Kayla Khairunnisa | D38: P | E38: 0 | F38: 0 | G38: 0 | H38: 0 | I38: 0 | J38: 0 | K38: 1 | L38: 1 | M38: 0 | N38: 1 | O38: 0 | P38: 0 | W38: =SUM(E38,H38,K38,N38,Q38,T38) -> 2 | X38: =SUM(F38,I38,L38,O38,R38,U38) -> 1 | Y38: =SUM(G38,J38,M38,P38,S38,V38) -> 0 | Z38: =SUM(W38:Y38) -> 3
A39: 16 | B39: 252610435 | C39: Kayla Nuraini Utomo | D39: P | E39: 1 | F39: 0 | G39: 0 | H39: 1 | I39: 0 | J39: 0 | K39: 0 | L39: 1 | M39: 0 | N39: 0 | O39: 1 | P39: 0 | W39: =SUM(E39,H39,K39,N39,Q39,T39) -> 2 | X39: =SUM(F39,I39,L39,O39,R39,U39) -> 2 | Y39: =SUM(G39,J39,M39,P39,S39,V39) -> 0 | Z39: =SUM(W39:Y39) -> 4
A40: 17 | B40: 252610436 | C40: Khaira Rahmanisa | D40: P | E40: 1 | F40: 0 | G40: 0 | H40: 0 | I40: 0 | J40: 0 | K40: 0 | L40: 0 | M40: 0 | N40: 0 | O40: 0 | P40: 0 | W40: =SUM(E40,H40,K40,N40,Q40,T40) -> 1 | X40: =SUM(F40,I40,L40,O40,R40,U40) -> 0 | Y40: =SUM(G40,J40,M40,P40,S40,V40) -> 0 | Z40: =SUM(W40:Y40) -> 1
... A59: 36 | B59: 252610551 | C59: Evan Fachrezi | D59: L | E59: 1 | F59: 1 | G59: 0 | H59: 0 | I59: 0 | J59: 0 | K59: 0 | L59: 0 | M59: 0 | N59: 1 | O59: 0 | P59: 0 | W59: =SUM(E59,H59,K59,N59,Q59,T59) -> 2 | X59: =SUM(F59,I59,L59,O59,R59,U59) -> 1 | Y59: =SUM(G59,J59,M59,P59,S59,V59) -> 0 | Z59: =SUM(W59:Y59) -> 3
A60: J U M L AH | E60: ='X TKJ 1'!E60 -> 17 | H60: ='X TKJ 1'!H60 -> 17 | K60: ='X TKJ 1'!K60 -> 13 | N60: ='X TKJ 1'!N60 -> 19 | W60: =SUM(W23:W59) -> 48 | X60: =SUM(X23:X59) -> 18 | Y60: =SUM(Y23:Y59) -> 32 | Z60: =SUM(Z23:Z59) -> 98
P62: Jumlah Ketidakhadiran | W62: =SUM(Z60) -> 98
P63: Jmlah Siswa | W63: ='X RPL 2'!A59 -> 37
P64: Presentase Ketidakhadiran | W64: =W62/(W63*W65) -> 0.04013104
P65: Jumlah Hari Efektif | W65: =SUM(E60:V60) -> 66
P66: Presentase Jumlah Kehadiran | W66: =(((W63*W65)-W62)/(W63*W65)) -> 0.95986896
C68: Mengetahui, | U68: ='X TKJ 1'!U68 -> Depok, Juli 2026
C69: Kepala SMK Taruna Bhakti | U69: Wali Kelas / Tingkat
C74: Aina Novera, S.Pd., MM. | U74: Annisa Anggi Rahayu, S.Ds.
C75: NIK. 19710203199510012 | U75: NIK. 19940516201809042

Sheet X PSPT 3
A16: DAFTAR HADIR PESERTA DIDIK SEMESTER GENAP
A17: SMK TARUNA BHAKTI
A18: TAHUN AJARAN 2025/2026
A20: ='X TKJ 1'!A20 -> SEMESTER GENAP | Y20: KELAS/TINGKAT : X PSPT 3
A21: NO | B21: NIPD | C21: NAMA PESERTA DIDIK | D21: JK | E21: JANUARI | H21: FEBRUARI | K21: MARET | N21: APRIL | Q21: MEI | T21: DESEMBER | W21: TOTAL ABSENSI
E22: S | F22: I | G22: A | H22: S | I22: I | J22: A | K22: S | L22: I | M22: A | N22: S | O22: I | P22: A | Q22: S | R22: I | S22: A | T22: S | U22: I | V22: A | W22: S | X22: I | Y22: A | Z22: T
A23: 1 | B23: 252610454 | C23: Amanda Putri Rahmadhani | D23: P | E23: 0 | F23: 0 | G23: 0 | H23: 0 | I23: 0 | J23: 0 | K23: 0 | L23: 1 | M23: 0 | N23: 0 | O23: 0 | P23: 0 | W23: =SUM(E23,H23,K23,N23,Q23,T23) -> 0 | X23: =SUM(F23,I23,L23,O23,R23,U23) -> 1 | Y23: =SUM(G23,J23,M23,P23,S23,V23) -> 0 | Z23: =SUM(W23:Y23) -> 1
A24: 2 | B24: 252610456 | C24: Andri Riswanto | D24: L | E24: 0 | F24: 0 | G24: 0 | H24: 1 | I24: 0 | J24: 0 | K24: 1 | L24: 1 | M24: 0 | N24: 2 | O24: 0 | P24: 0 | W24: =SUM(E24,H24,K24,N24,Q24,T24) -> 4 | X24: =SUM(F24,I24,L24,O24,R24,U24) -> 1 | Y24: =SUM(G24,J24,M24,P24,S24,V24) -> 0 | Z24: =SUM(W24:Y24) -> 5
A25: 3 | B25: 252610457 | C25: Anita Zahra Tussyifa | D25: P | E25: 0 | F25: 0 | G25: 0 | H25: 0 | I25: 0 | J25: 0 | K25: 1 | L25: 1 | M25: 0 | N25: 0 | O25: 0 | P25: 0 | W25: =SUM(E25,H25,K25,N25,Q25,T25) -> 1 | X25: =SUM(F25,I25,L25,O25,R25,U25) -> 1 | Y25: =SUM(G25,J25,M25,P25,S25,V25) -> 0 | Z25: =SUM(W25:Y25) -> 2
A26: 4 | B26: 252610458 | C26: Anyelir Devita Putri | D26: P | E26: 0 | F26: 0 | G26: 2 | H26: 1 | I26: 0 | J26: 1 | K26: 1 | L26: 1 | M26: 1 | N26: 0 | O26: 0 | P26: 0 | W26: =SUM(E26,H26,K26,N26,Q26,T26) -> 2 | X26: =SUM(F26,I26,L26,O26,R26,U26) -> 1 | Y26: =SUM(G26,J26,M26,P26,S26,V26) -> 4 | Z26: =SUM(W26:Y26) -> 7
A27: 5 | B27: 252610459 | C27: Azwa Kiara Ramadhani | D27: P | E27: 0 | F27: 0 | G27: 0 | H27: 1 | I27: 1 | J27: 0 | K27: 1 | L27: 0 | M27: 0 | N27: 0 | O27: 0 | P27: 0 | W27: =SUM(E27,H27,K27,N27,Q27,T27) -> 2 | X27: =SUM(F27,I27,L27,O27,R27,U27) -> 1 | Y27: =SUM(G27,J27,M27,P27,S27,V27) -> 0 | Z27: =SUM(W27:Y27) -> 3
A28: 6 | B28: 252610460 | C28: Bayu Dwi Apriyansyah | D28: L | E28: 0 | F28: 0 | G28: 0 | H28: 0 | I28: 0 | J28: 0 | K28: 0 | L28: 0 | M28: 0 | N28: 0 | O28: 0 | P28: 0 | W28: =SUM(E28,H28,K28,N28,Q28,T28) -> 0 | X28: =SUM(F28,I28,L28,O28,R28,U28) -> 0 | Y28: =SUM(G28,J28,M28,P28,S28,V28) -> 0 | Z28: =SUM(W28:Y28) -> 0
A29: 7 | B29: 252610461 | C29: Chilla Salwa Ramadhani | D29: P | E29: 4 | F29: 0 | G29: 0 | H29: 1 | I29: 0 | J29: 0 | K29: 0 | L29: 1 | M29: 0 | N29: 1 | O29: 1 | P29: 1 | W29: =SUM(E29,H29,K29,N29,Q29,T29) -> 6 | X29: =SUM(F29,I29,L29,O29,R29,U29) -> 2 | Y29: =SUM(G29,J29,M29,P29,S29,V29) -> 1 | Z29: =SUM(W29:Y29) -> 9
